Workbook

Sheet Resumen
A1: Árbol | B1: Focos | C1: Días | D1: Poder político | E1: Estabilidad (%) | F1: Apoyo a la guerra (%) | G1: Mano de obra | H1: Exp. ejército | I1: Exp. naval | J1: Exp. aérea | K1: Casillas de investigación | L1: Bonos de tecnología (usos) | M1: Fábricas civiles | N1: Fábricas militares | O1: Astilleros | P1: Infraestructura | Q1: Otros edificios (niveles) | R1: Equipo (unidades) | S1: Divisiones | T1: Cazas gratis | U1: Reclamos, núcleos y objetivos | V1: Espíritus (agregados) | W1: Puntaje en el acto (Pesos) | X1: Puntaje de espíritus (Espíritus) | Y1: Puntaje total | Z1: Total vs promedio de potencias | AA1: Focos excluyentes (se cuentan igual)
A2: EFE | B2: =COUNTIF('Por foco'!$A$2:$A$579,$A2) -> 70 | C2: =SUMIFS('Por foco'!$E$2:$E$579,'Por foco'!$A$2:$A$579,$A2) -> 4487 | D2: =SUMIFS('Por foco'!$F$2:$F$579,'Por foco'!$A$2:$A$579,$A2) -> 1470 | E2: =SUMIFS('Por foco'!$G$2:$G$579,'Por foco'!$A$2:$A$579,$A2) -> 0 | F2: =SUMIFS('Por foco'!$H$2:$H$579,'Por foco'!$A$2:$A$579,$A2) -> 15 | G2: =SUMIFS('Por foco'!$I$2:$I$579,'Por foco'!$A$2:$A$579,$A2) -> 80000 | H2: =SUMIFS('Por foco'!$J$2:$J$579,'Por foco'!$A$2:$A$579,$A2) -> 100 | I2: =SUMIFS('Por foco'!$K$2:$K$579,'Por foco'!$A$2:$A$579,$A2) -> 0 | J2: =SUMIFS('Por foco'!$L$2:$L$579,'Por foco'!$A$2:$A$579,$A2) -> 75 | K2: =SUMIFS('Por foco'!$M$2:$M$579,'Por foco'!$A$2:$A$579,$A2) -> 2 | L2: =SUMIFS('Por foco'!$N$2:$N$579,'Por foco'!$A$2:$A$579,$A2) -> 16 | M2: =SUMIFS('Por foco'!$O$2:$O$579,'Por foco'!$A$2:$A$579,$A2) -> 17 | N2: =SUMIFS('Por foco'!$P$2:$P$579,'Por foco'!$A$2:$A$579,$A2) -> 7 | O2: =SUMIFS('Por foco'!$Q$2:$Q$579,'Por foco'!$A$2:$A$579,$A2) -> 4 | P2: =SUMIFS('Por foco'!$R$2:$R$579,'Por foco'!$A$2:$A$579,$A2) -> 0 | Q2: =SUMIFS('Por foco'!$S$2:$S$579,'Por foco'!$A$2:$A$579,$A2) -> 2 | R2: =SUMIFS('Por foco'!$T$2:$T$579,'Por foco'!$A$2:$A$579,$A2) -> 0 | S2: =SUMIFS('Por foco'!$U$2:$U$579,'Por foco'!$A$2:$A$579,$A2) -> 0 | T2: =SUMIFS('Por foco'!$V$2:$V$579,'Por foco'!$A$2:$A$579,$A2) -> 150 | U2: =SUMIFS('Por foco'!$W$2:$W$579,'Por foco'!$A$2:$A$579,$A2) -> 11 | V2: =SUMIFS('Por foco'!$X$2:$X$579,'Por foco'!$A$2:$A$579,$A2) -> 29 | W2: =C2*Pesos!$B$2+D2*Pesos!$B$3+E2*Pesos!$B$4+F2*Pesos!$B$5+G2*Pesos!$B$6+H2*Pesos!$B$7+I2*Pesos!$B$8+J2*Pesos!$B$9+K2*Pesos!$B$10+L2*Pesos!$B$11+M2*Pesos!$B$12+N2*Pesos!$B$13+O2*Pesos!$B$14+P2*Pesos!$B$15+Q2*Pesos!$B$16+R2*Pesos!$B$17+S2*Pesos!$B$18+T2*Pesos!$B$19+U2*Pesos!$B$20+V2*Pesos!$B$21 -> 5740 | X2: =Espíritus!C35 -> 4826 | Y2: =W2+X2 -> 10566 | Z2: =IF($Y$16=0,0,Y2/$Y$16-1) -> -0.05344845 | AA2: =COUNTIFS('Por foco'!$A$2:$A$579,$A2,'Por foco'!$AA$2:$AA$579,"?*") -> 4
A3: ASC | B3: =COUNTIF('Por foco'!$A$2:$A$579,$A3) -> 69 | C3: =SUMIFS('Por foco'!$E$2:$E$579,'Por foco'!$A$2:$A$579,$A3) -> 4466 | D3: =SUMIFS('Por foco'!$F$2:$F$579,'Por foco'!$A$2:$A$579,$A3) -> 1270 | E3: =SUMIFS('Por foco'!$G$2:$G$579,'Por foco'!$A$2:$A$579,$A3) -> 5 | F3: =SUMIFS('Por foco'!$H$2:$H$579,'Por foco'!$A$2:$A$579,$A3) -> 15 | G3: =SUMIFS('Por foco'!$I$2:$I$579,'Por foco'!$A$2:$A$579,$A3) -> 100000 | H3: =SUMIFS('Por foco'!$J$2:$J$579,'Por foco'!$A$2:$A$579,$A3) -> 75 | I3: =SUMIFS('Por foco'!$K$2:$K$579,'Por foco'!$A$2:$A$579,$A3) -> 0 | J3: =SUMIFS('Por foco'!$L$2:$L$579,'Por foco'!$A$2:$A$579,$A3) -> 0 | K3: =SUMIFS('Por foco'!$M$2:$M$579,'Por foco'!$A$2:$A$579,$A3) -> 5 | L3: =SUMIFS('Por foco'!$N$2:$N$579,'Por foco'!$A$2:$A$579,$A3) -> 12 | M3: =SUMIFS('Por foco'!$O$2:$O$579,'Por foco'!$A$2:$A$579,$A3) -> 11 | N3: =SUMIFS('Por foco'!$P$2:$P$579,'Por foco'!$A$2:$A$579,$A3) -> 6 | O3: =SUMIFS('Por foco'!$Q$2:$Q$579,'Por foco'!$A$2:$A$579,$A3) -> 7 | P3: =SUMIFS('Por foco'!$R$2:$R$579,'Por foco'!$A$2:$A$579,$A3) -> 1 | Q3: =SUMIFS('Por foco'!$S$2:$S$579,'Por foco'!$A$2:$A$579,$A3) -> 0 | R3: =SUMIFS('Por foco'!$T$2:$T$579,'Por foco'!$A$2:$A$579,$A3) -> 0 | S3: =SUMIFS('Por foco'!$U$2:$U$579,'Por foco'!$A$2:$A$579,$A3) -> 0 | T3: =SUMIFS('Por foco'!$V$2:$V$579,'Por foco'!$A$2:$A$579,$A3) -> 100 | U3: =SUMIFS('Por foco'!$W$2:$W$579,'Por foco'!$A$2:$A$579,$A3) -> 8 | V3: =SUMIFS('Por foco'!$X$2:$X$579,'Por foco'!$A$2:$A$579,$A3) -> 19 | W3: =C3*Pesos!$B$2+D3*Pesos!$B$3+E3*Pesos!$B$4+F3*Pesos!$B$5+G3*Pesos!$B$6+H3*Pesos!$B$7+I3*Pesos!$B$8+J3*Pesos!$B$9+K3*Pesos!$B$10+L3*Pesos!$B$11+M3*Pesos!$B$12+N3*Pesos!$B$13+O3*Pesos!$B$14+P3*Pesos!$B$15+Q3*Pesos!$B$16+R3*Pesos!$B$17+S3*Pesos!$B$18+T3*Pesos!$B$19+U3*Pesos!$B$20+V3*Pesos!$B$21 -> 5740 | X3: =Espíritus!D35 -> 5590.5 | Y3: =W3+X3 -> 11330.5 | Z3: =IF($Y$16=0,0,Y3/$Y$16-1) -> 0.015039025 | AA3: =COUNTIFS('Por foco'!$A$2:$A$579,$A3,'Por foco'!$AA$2:$AA$579,"?*") -> 4
A4: FCU | B4: =COUNTIF('Por foco'!$A$2:$A$579,$A4) -> 67 | C4: =SUMIFS('Por foco'!$E$2:$E$579,'Por foco'!$A$2:$A$579,$A4) -> 4221 | D4: =SUMIFS('Por foco'!$F$2:$F$579,'Por foco'!$A$2:$A$579,$A4) -> 1570 | E4: =SUMIFS('Por foco'!$G$2:$G$579,'Por foco'!$A$2:$A$579,$A4) -> 15 | F4: =SUMIFS('Por foco'!$H$2:$H$579,'Por foco'!$A$2:$A$579,$A4) -> 15 | G4: =SUMIFS('Por foco'!$I$2:$I$579,'Por foco'!$A$2:$A$579,$A4) -> 100000 | H4: =SUMIFS('Por foco'!$J$2:$J$579,'Por foco'!$A$2:$A$579,$A4) -> 75 | I4: =SUMIFS('Por foco'!$K$2:$K$579,'Por foco'!$A$2:$A$579,$A4) -> 50 | J4: =SUMIFS('Por foco'!$L$2:$L$579,'Por foco'!$A$2:$A$579,$A4) -> 0 | K4: =SUMIFS('Por foco'!$M$2:$M$579,'Por foco'!$A$2:$A$579,$A4) -> 2 | L4: =SUMIFS('Por foco'!$N$2:$N$579,'Por foco'!$A$2:$A$579,$A4) -> 10 | M4: =SUMIFS('Por foco'!$O$2:$O$579,'Por foco'!$A$2:$A$579,$A4) -> 16 | N4: =SUMIFS('Por foco'!$P$2:$P$579,'Por foco'!$A$2:$A$579,$A4) -> 8 | O4: =SUMIFS('Por foco'!$Q$2:$Q$579,'Por foco'!$A$2:$A$579,$A4) -> 9 | P4: =SUMIFS('Por foco'!$R$2:$R$579,'Por foco'!$A$2:$A$579,$A4) -> 4 | Q4: =SUMIFS('Por foco'!$S$2:$S$579,'Por foco'!$A$2:$A$579,$A4) -> 0 | R4: =SUMIFS('Por foco'!$T$2:$T$579,'Por foco'!$A$2:$A$579,$A4) -> 0 | S4: =SUMIFS('Por foco'!$U$2:$U$579,'Por foco'!$A$2:$A$579,$A4) -> 0 | T4: =SUMIFS('Por foco'!$V$2:$V$579,'Por foco'!$A$2:$A$579,$A4) -> 120 | U4: =SUMIFS('Por foco'!$W$2:$W$579,'Por foco'!$A$2:$A$579,$A4) -> 7 | V4: =SUMIFS('Por foco'!$X$2:$X$579,'Por foco'!$A$2:$A$579,$A4) -> 23 | W4: =C4*Pesos!$B$2+D4*Pesos!$B$3+E4*Pesos!$B$4+F4*Pesos!$B$5+G4*Pesos!$B$6+H4*Pesos!$B$7+I4*Pesos!$B$8+J4*Pesos!$B$9+K4*Pesos!$B$10+L4*Pesos!$B$11+M4*Pesos!$B$12+N4*Pesos!$B$13+O4*Pesos!$B$14+P4*Pesos!$B$15+Q4*Pesos!$B$16+R4*Pesos!$B$17+S4*Pesos!$B$18+T4*Pesos!$B$19+U4*Pesos!$B$20+V4*Pesos!$B$21 -> 6055 | X4: =Espíritus!E35 -> 4468.5 | Y4: =W4+X4 -> 10523.5 | Z4: =IF($Y$16=0,0,Y4/$Y$16-1) -> -0.057255798 | AA4: =COUNTIFS('Por foco'!$A$2:$A$579,$A4,'Por foco'!$AA$2:$AA$579,"?*") -> 6
A5: HSN | B5: =COUNTIF('Por foco'!$A$2:$A$579,$A5) -> 64 | C5: =SUMIFS('Por foco'!$E$2:$E$579,'Por foco'!$A$2:$A$579,$A5) -> 4137 | D5: =SUMIFS('Por foco'!$F$2:$F$579,'Por foco'!$A$2:$A$579,$A5) -> 1720 | E5: =SUMIFS('Por foco'!$G$2:$G$579,'Por foco'!$A$2:$A$579,$A5) -> 5 | F5: =SUMIFS('Por foco'!$H$2:$H$579,'Por foco'!$A$2:$A$579,$A5) -> 15 | G5: =SUMIFS('Por foco'!$I$2:$I$579,'Por foco'!$A$2:$A$579,$A5) -> 75000 | H5: =SUMIFS('Por foco'!$J$2:$J$579,'Por foco'!$A$2:$A$579,$A5) -> 150 | I5: =SUMIFS('Por foco'!$K$2:$K$579,'Por foco'!$A$2:$A$579,$A5) -> 255 | J5: =SUMIFS('Por foco'!$L$2:$L$579,'Por foco'!$A$2:$A$579,$A5) -> 0 | K5: =SUMIFS('Por foco'!$M$2:$M$579,'Por foco'!$A$2:$A$579,$A5) -> 2 | L5: =SUMIFS('Por foco'!$N$2:$N$579,'Por foco'!$A$2:$A$579,$A5) -> 7 | M5: =SUMIFS('Por foco'!$O$2:$O$579,'Por foco'!$A$2:$A$579,$A5) -> 9 | N5: =SUMIFS('Por foco'!$P$2:$P$579,'Por foco'!$A$2:$A$579,$A5) -> 3 | O5: =SUMIFS('Por foco'!$Q$2:$Q$579,'Por foco'!$A$2:$A$579,$A5) -> 21 | P5: =SUMIFS('Por foco'!$R$2:$R$579,'Por foco'!$A$2:$A$579,$A5) -> 7 | Q5: =SUMIFS('Por foco'!$S$2:$S$579,'Por foco'!$A$2:$A$579,$A5) -> 3 | R5: =SUMIFS('Por foco'!$T$2:$T$579,'Por foco'!$A$2:$A$579,$A5) -> 0 | S5: =SUMIFS('Por foco'!$U$2:$U$579,'Por foco'!$A$2:$A$579,$A5) -> 0 | T5: =SUMIFS('Por foco'!$V$2:$V$579,'Por foco'!$A$2:$A$579,$A5) -> 80 | U5: =SUMIFS('Por foco'!$W$2:$W$579,'Por foco'!$A$2:$A$579,$A5) -> 12 | V5: =SUMIFS('Por foco'!$X$2:$X$579,'Por foco'!$A$2:$A$579,$A5) -> 16 | W5: =C5*Pesos!$B$2+D5*Pesos!$B$3+E5*Pesos!$B$4+F5*Pesos!$B$5+G5*Pesos!$B$6+H5*Pesos!$B$7+I5*Pesos!$B$8+J5*Pesos!$B$9+K5*Pesos!$B$10+L5*Pesos!$B$11+M5*Pesos!$B$12+N5*Pesos!$B$13+O5*Pesos!$B$14+P5*Pesos!$B$15+Q5*Pesos!$B$16+R5*Pesos!$B$17+S5*Pesos!$B$18+T5*Pesos!$B$19+U5*Pesos!$B$20+V5*Pesos!$B$21 -> 6035 | X5: =Espíritus!F35 -> 3207.5 | Y5: =W5+X5 -> 9242.5 | Z5: =IF($Y$16=0,0,Y5/$Y$16-1) -> -0.17201375 | AA5: =COUNTIFS('Por foco'!$A$2:$A$579,$A5,'Por foco'!$AA$2:$AA$579,"?*") -> 4
A6: NAS | B6: =COUNTIF('Por foco'!$A$2:$A$579,$A6) -> 68 | C6: =SUMIFS('Por foco'!$E$2:$E$579,'Por foco'!$A$2:$A$579,$A6) -> 4417 | D6: =SUMIFS('Por foco'!$F$2:$F$579,'Por foco'!$A$2:$A$579,$A6) -> 1170 | E6: =SUMIFS('Por foco'!$G$2:$G$579,'Por foco'!$A$2:$A$579,$A6) -> 38 | F6: =SUMIFS('Por foco'!$H$2:$H$579,'Por foco'!$A$2:$A$579,$A6) -> 25 | G6: =SUMIFS('Por foco'!$I$2:$I$579,'Por foco'!$A$2:$A$579,$A6) -> 80000 | H6: =SUMIFS('Por foco'!$J$2:$J$579,'Por foco'!$A$2:$A$579,$A6) -> 325 | I6: =SUMIFS('Por foco'!$K$2:$K$579,'Por foco'!$A$2:$A$579,$A6) -> 25 | J6: =SUMIFS('Por foco'!$L$2:$L$579,'Por foco'!$A$2:$A$579,$A6) -> 50 | K6: =SUMIFS('Por foco'!$M$2:$M$579,'Por foco'!$A$2:$A$579,$A6) -> 4 | L6: =SUMIFS('Por foco'!$N$2:$N$579,'Por foco'!$A$2:$A$579,$A6) -> 16 | M6: =SUMIFS('Por foco'!$O$2:$O$579,'Por foco'!$A$2:$A$579,$A6) -> 16 | N6: =SUMIFS('Por foco'!$P$2:$P$579,'Por foco'!$A$2:$A$579,$A6) -> 2 | O6: =SUMIFS('Por foco'!$Q$2:$Q$579,'Por foco'!$A$2:$A$579,$A6) -> 4 | P6: =SUMIFS('Por foco'!$R$2:$R$579,'Por foco'!$A$2:$A$579,$A6) -> 2 | Q6: =SUMIFS('Por foco'!$S$2:$S$579,'Por foco'!$A$2:$A$579,$A6) -> 5 | R6: =SUMIFS('Por foco'!$T$2:$T$579,'Por foco'!$A$2:$A$579,$A6) -> 0 | S6: =SUMIFS('Por foco'!$U$2:$U$579,'Por foco'!$A$2:$A$579,$A6) -> 0 | T6: =SUMIFS('Por foco'!$V$2:$V$579,'Por foco'!$A$2:$A$579,$A6) -> 300 | U6: =SUMIFS('Por foco'!$W$2:$W$579,'Por foco'!$A$2:$A$579,$A6) -> 22 | V6: =SUMIFS('Por foco'!$X$2:$X$579,'Por foco'!$A$2:$A$579,$A6) -> 20 | W6: =C6*Pesos!$B$2+D6*Pesos!$B$3+E6*Pesos!$B$4+F6*Pesos!$B$5+G6*Pesos!$B$6+H6*Pesos!$B$7+I6*Pesos!$B$8+J6*Pesos!$B$9+K6*Pesos!$B$10+L6*Pesos!$B$11+M6*Pesos!$B$12+N6*Pesos!$B$13+O6*Pesos!$B$14+P6*Pesos!$B$15+Q6*Pesos!$B$16+R6*Pesos!$B$17+S6*Pesos!$B$18+T6*Pesos!$B$19+U6*Pesos!$B$20+V6*Pesos!$B$21 -> 6580 | X6: =Espíritus!G35 -> 5172.5 | Y6: =W6+X6 -> 11752.5 | Z6: =IF($Y$16=0,0,Y6/$Y$16-1) -> 0.052843753 | AA6: =COUNTIFS('Por foco'!$A$2:$A$579,$A6,'Por foco'!$AA$2:$AA$579,"?*") -> 4
A7: SHD | B7: =COUNTIF('Por foco'!$A$2:$A$579,$A7) -> 65 | C7: =SUMIFS('Por foco'!$E$2:$E$579,'Por foco'!$A$2:$A$579,$A7) -> 4123 | D7: =SUMIFS('Por foco'!$F$2:$F$579,'Por foco'!$A$2:$A$579,$A7) -> 1120 | E7: =SUMIFS('Por foco'!$G$2:$G$579,'Por foco'!$A$2:$A$579,$A7) -> 18 | F7: =SUMIFS('Por foco'!$H$2:$H$579,'Por foco'!$A$2:$A$579,$A7) -> 15 | G7: =SUMIFS('Por foco'!$I$2:$I$579,'Por foco'!$A$2:$A$579,$A7) -> 300000 | H7: =SUMIFS('Por foco'!$J$2:$J$579,'Por foco'!$A$2:$A$579,$A7) -> 375 | I7: =SUMIFS('Por foco'!$K$2:$K$579,'Por foco'!$A$2:$A$579,$A7) -> 25 | J7: =SUMIFS('Por foco'!$L$2:$L$579,'Por foco'!$A$2:$A$579,$A7) -> 50 | K7: =SUMIFS('Por foco'!$M$2:$M$579,'Por foco'!$A$2:$A$579,$A7) -> 4 | L7: =SUMIFS('Por foco'!$N$2:$N$579,'Por foco'!$A$2:$A$579,$A7) -> 20 | M7: =SUMIFS('Por foco'!$O$2:$O$579,'Por foco'!$A$2:$A$579,$A7) -> 17 | N7: =SUMIFS('Por foco'!$P$2:$P$579,'Por foco'!$A$2:$A$579,$A7) -> 4 | O7: =SUMIFS('Por foco'!$Q$2:$Q$579,'Por foco'!$A$2:$A$579,$A7) -> 4 | P7: =SUMIFS('Por foco'!$R$2:$R$579,'Por foco'!$A$2:$A$579,$A7) -> 5 | Q7: =SUMIFS('Por foco'!$S$2:$S$579,'Por foco'!$A$2:$A$579,$A7) -> 2 | R7: =SUMIFS('Por foco'!$T$2:$T$579,'Por foco'!$A$2:$A$579,$A7) -> 0 | S7: =SUMIFS('Por foco'!$U$2:$U$579,'Por foco'!$A$2:$A$579,$A7) -> 0 | T7: =SUMIFS('Por foco'!$V$2:$V$579,'Por foco'!$A$2:$A$579,$A7) -> 100 | U7: =SUMIFS('Por foco'!$W$2:$W$579,'Por foco'!$A$2:$A$579,$A7) -> 10 | V7: =SUMIFS('Por foco'!$X$2:$X$579,'Por foco'!$A$2:$A$579,$A7) -> 18 | W7: =C7*Pesos!$B$2+D7*Pesos!$B$3+E7*Pesos!$B$4+F7*Pesos!$B$5+G7*Pesos!$B$6+H7*Pesos!$B$7+I7*Pesos!$B$8+J7*Pesos!$B$9+K7*Pesos!$B$10+L7*Pesos!$B$11+M7*Pesos!$B$12+N7*Pesos!$B$13+O7*Pesos!$B$14+P7*Pesos!$B$15+Q7*Pesos!$B$16+R7*Pesos!$B$17+S7*Pesos!$B$18+T7*Pesos!$B$19+U7*Pesos!$B$20+V7*Pesos!$B$21 -> 6775 | X7: =Espíritus!H35 -> 4694.5 | Y7: =W7+X7 -> 11469.5 | Z7: =IF($Y$16=0,0,Y7/$Y$16-1) -> 0.027491293 | AA7: =COUNTIFS('Por foco'!$A$2:$A$579,$A7,'Por foco'!$AA$2:$AA$579,"?*") -> 4
A8: APF | B8: =COUNTIF('Por foco'!$A$2:$A$579,$A8) -> 62 | C8: =SUMIFS('Por foco'!$E$2:$E$579,'Por foco'!$A$2:$A$579,$A8) -> 4025 | D8: =SUMIFS('Por foco'!$F$2:$F$579,'Por foco'!$A$2:$A$579,$A8) -> 1070 | E8: =SUMIFS('Por foco'!$G$2:$G$579,'Por foco'!$A$2:$A$579,$A8) -> 18 | F8: =SUMIFS('Por foco'!$H$2:$H$579,'Por foco'!$A$2:$A$579,$A8) -> 25 | G8: =SUMIFS('Por foco'!$I$2:$I$579,'Por foco'!$A$2:$A$579,$A8) -> 320000 | H8: =SUMIFS('Por foco'!$J$2:$J$579,'Por foco'!$A$2:$A$579,$A8) -> 425 | I8: =SUMIFS('Por foco'!$K$2:$K$579,'Por foco'!$A$2:$A$579,$A8) -> 25 | J8: =SUMIFS('Por foco'!$L$2:$L$579,'Por foco'!$A$2:$A$579,$A8) -> 50 | K8: =SUMIFS('Por foco'!$M$2:$M$579,'Por foco'!$A$2:$A$579,$A8) -> 3 | L8: =SUMIFS('Por foco'!$N$2:$N$579,'Por foco'!$A$2:$A$579,$A8) -> 21 | M8: =SUMIFS('Por foco'!$O$2:$O$579,'Por foco'!$A$2:$A$579,$A8) -> 19 | N8: =SUMIFS('Por foco'!$P$2:$P$579,'Por foco'!$A$2:$A$579,$A8) -> 2 | O8: =SUMIFS('Por foco'!$Q$2:$Q$579,'Por foco'!$A$2:$A$579,$A8) -> 5 | P8: =SUMIFS('Por foco'!$R$2:$R$579,'Por foco'!$A$2:$A$579,$A8) -> 4 | Q8: =SUMIFS('Por foco'!$S$2:$S$579,'Por foco'!$A$2:$A$579,$A8) -> 3 | R8: =SUMIFS('Por foco'!$T$2:$T$579,'Por foco'!$A$2:$A$579,$A8) -> 0 | S8: =SUMIFS('Por foco'!$U$2:$U$579,'Por foco'!$A$2:$A$579,$A8) -> 0 | T8: =SUMIFS('Por foco'!$V$2:$V$579,'Por foco'!$A$2:$A$579,$A8) -> 100 | U8: =SUMIFS('Por foco'!$W$2:$W$579,'Por foco'!$A$2:$A$579,$A8) -> 15 | V8: =SUMIFS('Por foco'!$X$2:$X$579,'Por foco'!$A$2:$A$579,$A8) -> 20 | W8: =C8*Pesos!$B$2+D8*Pesos!$B$3+E8*Pesos!$B$4+F8*Pesos!$B$5+G8*Pesos!$B$6+H8*Pesos!$B$7+I8*Pesos!$B$8+J8*Pesos!$B$9+K8*Pesos!$B$10+L8*Pesos!$B$11+M8*Pesos!$B$12+N8*Pesos!$B$13+O8*Pesos!$B$14+P8*Pesos!$B$15+Q8*Pesos!$B$16+R8*Pesos!$B$17+S8*Pesos!$B$18+T8*Pesos!$B$19+U8*Pesos!$B$20+V8*Pesos!$B$21 -> 6815 | X8: =Espíritus!I35 -> 5479.5 | Y8: =W8+X8 -> 12294.5 | Z8: =IF($Y$16=0,0,Y8/$Y$16-1) -> 0.10139864 | AA8: =COUNTIFS('Por foco'!$A$2:$A$579,$A8,'Por foco'!$AA$2:$AA$579,"?*") -> 4
A9: NRE | B9: =COUNTIF('Por foco'!$A$2:$A$579,$A9) -> 67 | C9: =SUMIFS('Por foco'!$E$2:$E$579,'Por foco'!$A$2:$A$579,$A9) -> 4606 | D9: =SUMIFS('Por foco'!$F$2:$F$579,'Por foco'!$A$2:$A$579,$A9) -> 1070 | E9: =SUMIFS('Por foco'!$G$2:$G$579,'Por foco'!$A$2:$A$579,$A9) -> 19 | F9: =SUMIFS('Por foco'!$H$2:$H$579,'Por foco'!$A$2:$A$579,$A9) -> 20 | G9: =SUMIFS('Por foco'!$I$2:$I$579,'Por foco'!$A$2:$A$579,$A9) -> 500000 | H9: =SUMIFS('Por foco'!$J$2:$J$579,'Por foco'!$A$2:$A$579,$A9) -> 225 | I9: =SUMIFS('Por foco'!$K$2:$K$579,'Por foco'!$A$2:$A$579,$A9) -> 25 | J9: =SUMIFS('Por foco'!$L$2:$L$579,'Por foco'!$A$2:$A$579,$A9) -> 75 | K9: =SUMIFS('Por foco'!$M$2:$M$579,'Por foco'!$A$2:$A$579,$A9) -> 3 | L9: =SUMIFS('Por foco'!$N$2:$N$579,'Por foco'!$A$2:$A$579,$A9) -> 15 | M9: =SUMIFS('Por foco'!$O$2:$O$579,'Por foco'!$A$2:$A$579,$A9) -> 11 | N9: =SUMIFS('Por foco'!$P$2:$P$579,'Por foco'!$A$2:$A$579,$A9) -> 8 | O9: =SUMIFS('Por foco'!$Q$2:$Q$579,'Por foco'!$A$2:$A$579,$A9) -> 4 | P9: =SUMIFS('Por foco'!$R$2:$R$579,'Por foco'!$A$2:$A$579,$A9) -> 6 | Q9: =SUMIFS('Por foco'!$S$2:$S$579,'Por foco'!$A$2:$A$579,$A9) -> 2 | R9: =SUMIFS('Por foco'!$T$2:$T$579,'Por foco'!$A$2:$A$579,$A9) -> 0 | S9: =SUMIFS('Por foco'!$U$2:$U$579,'Por foco'!$A$2:$A$579,$A9) -> 0 | T9: =SUMIFS('Por foco'!$V$2:$V$579,'Por foco'!$A$2:$A$579,$A9) -> 100 | U9: =SUMIFS('Por foco'!$W$2:$W$579,'Por foco'!$A$2:$A$579,$A9) -> 12 | V9: =SUMIFS('Por foco'!$X$2:$X$579,'Por foco'!$A$2:$A$579,$A9) -> 24 | W9: =C9*Pesos!$B$2+D9*Pesos!$B$3+E9*Pesos!$B$4+F9*Pesos!$B$5+G9*Pesos!$B$6+H9*Pesos!$B$7+I9*Pesos!$B$8+J9*Pesos!$B$9+K9*Pesos!$B$10+L9*Pesos!$B$11+M9*Pesos!$B$12+N9*Pesos!$B$13+O9*Pesos!$B$14+P9*Pesos!$B$15+Q9*Pesos!$B$16+R9*Pesos!$B$17+S9*Pesos!$B$18+T9*Pesos!$B$19+U9*Pesos!$B$20+V9*Pesos!$B$21 -> 6400 | X9: =Espíritus!J35 -> 5722 | Y9: =W9+X9 -> 12122 | Z9: =IF($Y$16=0,0,Y9/$Y$16-1) -> 0.085945286 | AA9: =COUNTIFS('Por foco'!$A$2:$A$579,$A9,'Por foco'!$AA$2:$AA$579,"?*") -> 4
A10: ZWB | B10: =COUNTIF('Por foco'!$A$2:$A$579,$A10) -> 7 | C10: =SUMIFS('Por foco'!$E$2:$E$579,'Por foco'!$A$2:$A$579,$A10) -> 245 | D10: =SUMIFS('Por foco'!$F$2:$F$579,'Por foco'!$A$2:$A$579,$A10) -> 0 | E10: =SUMIFS('Por foco'!$G$2:$G$579,'Por foco'!$A$2:$A$579,$A10) -> 0 | F10: =SUMIFS('Por foco'!$H$2:$H$579,'Por foco'!$A$2:$A$579,$A10) -> 0 | G10: =SUMIFS('Por foco'!$I$2:$I$579,'Por foco'!$A$2:$A$579,$A10) -> 60000 | H10: =SUMIFS('Por foco'!$J$2:$J$579,'Por foco'!$A$2:$A$579,$A10) -> 0 | I10: =SUMIFS('Por foco'!$K$2:$K$579,'Por foco'!$A$2:$A$579,$A10) -> 0 | J10: =SUMIFS('Por foco'!$L$2:$L$579,'Por foco'!$A$2:$A$579,$A10) -> 0 | K10: =SUMIFS('Por foco'!$M$2:$M$579,'Por foco'!$A$2:$A$579,$A10) -> 0 | L10: =SUMIFS('Por foco'!$N$2:$N$579,'Por foco'!$A$2:$A$579,$A10) -> 0 | M10: =SUMIFS('Por foco'!$O$2:$O$579,'Por foco'!$A$2:$A$579,$A10) -> 0 | N10: =SUMIFS('Por foco'!$P$2:$P$579,'Por foco'!$A$2:$A$579,$A10) -> 0 | O10: =SUMIFS('Por foco'!$Q$2:$Q$579,'Por foco'!$A$2:$A$579,$A10) -> 0 | P10: =SUMIFS('Por foco'!$R$2:$R$579,'Por foco'!$A$2:$A$579,$A10) -> 0 | Q10: =SUMIFS('Por foco'!$S$2:$S$579,'Por foco'!$A$2:$A$579,$A10) -> 0 | R10: =SUMIFS('Por foco'!$T$2:$T$579,'Por foco'!$A$2:$A$579,$A10) -> 3500 | S10: =SUMIFS('Por foco'!$U$2:$U$579,'Por foco'!$A$2:$A$579,$A10) -> 0 | T10: =SUMIFS('Por foco'!$V$2:$V$579,'Por foco'!$A$2:$A$579,$A10) -> 0 | U10: =SUMIFS('Por foco'!$W$2:$W$579,'Por foco'!$A$2:$A$579,$A10) -> 0 | V10: =SUMIFS('Por foco'!$X$2:$X$579,'Por foco'!$A$2:$A$579,$A10) -> 7 | W10: =C10*Pesos!$B$2+D10*Pesos!$B$3+E10*Pesos!$B$4+F10*Pesos!$B$5+G10*Pesos!$B$6+H10*Pesos!$B$7+I10*Pesos!$B$8+J10*Pesos!$B$9+K10*Pesos!$B$10+L10*Pesos!$B$11+M10*Pesos!$B$12+N10*Pesos!$B$13+O10*Pesos!$B$14+P10*Pesos!$B$15+Q10*Pesos!$B$16+R10*Pesos!$B$17+S10*Pesos!$B$18+T10*Pesos!$B$19+U10*Pesos!$B$20+V10*Pesos!$B$21 -> 190 | X10: =Espíritus!K35 -> 2030 | Y10: =W10+X10 -> 2220 | Z10: =IF($Y$16=0,0,Y10/$Y$16-1) -> -0.80112205 | AA10: =COUNTIFS('Por foco'!$A$2:$A$579,$A10,'Por foco'!$AA$2:$AA$579,"?*") -> 0
A11: ZWE | B11: =COUNTIF('Por foco'!$A$2:$A$579,$A11) -> 7 | C11: =SUMIFS('Por foco'!$E$2:$E$579,'Por foco'!$A$2:$A$579,$A11) -> 245 | D11: =SUMIFS('Por foco'!$F$2:$F$579,'Por foco'!$A$2:$A$579,$A11) -> 0 | E11: =SUMIFS('Por foco'!$G$2:$G$579,'Por foco'!$A$2:$A$579,$A11) -> 0 | F11: =SUMIFS('Por foco'!$H$2:$H$579,'Por foco'!$A$2:$A$579,$A11) -> 0 | G11: =SUMIFS('Por foco'!$I$2:$I$579,'Por foco'!$A$2:$A$579,$A11) -> 1340000 | H11: =SUMIFS('Por foco'!$J$2:$J$579,'Por foco'!$A$2:$A$579,$A11) -> 0 | I11: =SUMIFS('Por foco'!$K$2:$K$579,'Por foco'!$A$2:$A$579,$A11) -> 0 | J11: =SUMIFS('Por foco'!$L$2:$L$579,'Por foco'!$A$2:$A$579,$A11) -> 0 | K11: =SUMIFS('Por foco'!$M$2:$M$579,'Por foco'!$A$2:$A$579,$A11) -> 0 | L11: =SUMIFS('Por foco'!$N$2:$N$579,'Por foco'!$A$2:$A$579,$A11) -> 0 | M11: =SUMIFS('Por foco'!$O$2:$O$579,'Por foco'!$A$2:$A$579,$A11) -> 0 | N11: =SUMIFS('Por foco'!$P$2:$P$579,'Por foco'!$A$2:$A$579,$A11) -> 0 | O11: =SUMIFS('Por foco'!$Q$2:$Q$579,'Por foco'!$A$2:$A$579,$A11) -> 0 | P11: =SUMIFS('Por foco'!$R$2:$R$579,'Por foco'!$A$2:$A$579,$A11) -> 0 | Q11: =SUMIFS('Por foco'!$S$2:$S$579,'Por foco'!$A$2:$A$579,$A11) -> 0 | R11: =SUMIFS('Por foco'!$T$2:$T$579,'Por foco'!$A$2:$A$579,$A11) -> 30150 | S11: =SUMIFS('Por foco'!$U$2:$U$579,'Por foco'!$A$2:$A$579,$A11) -> 6 | T11: =SUMIFS('Por foco'!$V$2:$V$579,'Por foco'!$A$2:$A$579,$A11) -> 0 | U11: =SUMIFS('Por foco'!$W$2:$W$579,'Por foco'!$A$2:$A$579,$A11) -> 2 | V11: =SUMIFS('Por foco'!$X$2:$X$579,'Por foco'!$A$2:$A$579,$A11) -> 7 | W11: =C11*Pesos!$B$2+D11*Pesos!$B$3+E11*Pesos!$B$4+F11*Pesos!$B$5+G11*Pesos!$B$6+H11*Pesos!$B$7+I11*Pesos!$B$8+J11*Pesos!$B$9+K11*Pesos!$B$10+L11*Pesos!$B$11+M11*Pesos!$B$12+N11*Pesos!$B$13+O11*Pesos!$B$14+P11*Pesos!$B$15+Q11*Pesos!$B$16+R11*Pesos!$B$17+S11*Pesos!$B$18+T11*Pesos!$B$19+U11*Pesos!$B$20+V11*Pesos!$B$21 -> 3563 | X11: =Espíritus!L35 -> 3673 | Y11: =W11+X11 -> 7236 | Z11: =IF($Y$16=0,0,Y11/$Y$16-1) -> -0.35176538 | AA11: =COUNTIFS('Por foco'!$A$2:$A$579,$A11,'Por foco'!$AA$2:$AA$579,"?*") -> 0
A12: ZWI | B12: =COUNTIF('Por foco'!$A$2:$A$579,$A12) -> 7 | C12: =SUMIFS('Por foco'!$E$2:$E$579,'Por foco'!$A$2:$A$579,$A12) -> 245 | D12: =SUMIFS('Por foco'!$F$2:$F$579,'Por foco'!$A$2:$A$579,$A12) -> 0 | E12: =SUMIFS('Por foco'!$G$2:$G$579,'Por foco'!$A$2:$A$579,$A12) -> 0 | F12: =SUMIFS('Por foco'!$H$2:$H$579,'Por foco'!$A$2:$A$579,$A12) -> 0 | G12: =SUMIFS('Por foco'!$I$2:$I$579,'Por foco'!$A$2:$A$579,$A12) -> 1840000 | H12: =SUMIFS('Por foco'!$J$2:$J$579,'Por foco'!$A$2:$A$579,$A12) -> 0 | I12: =SUMIFS('Por foco'!$K$2:$K$579,'Por foco'!$A$2:$A$579,$A12) -> 0 | J12: =SUMIFS('Por foco'!$L$2:$L$579,'Por foco'!$A$2:$A$579,$A12) -> 0 | K12: =SUMIFS('Por foco'!$M$2:$M$579,'Por foco'!$A$2:$A$579,$A12) -> 0 | L12: =SUMIFS('Por foco'!$N$2:$N$579,'Por foco'!$A$2:$A$579,$A12) -> 0 | M12: =SUMIFS('Por foco'!$O$2:$O$579,'Por foco'!$A$2:$A$579,$A12) -> 0 | N12: =SUMIFS('Por foco'!$P$2:$P$579,'Por foco'!$A$2:$A$579,$A12) -> 0 | O12: =SUMIFS('Por foco'!$Q$2:$Q$579,'Por foco'!$A$2:$A$579,$A12) -> 0 | P12: =SUMIFS('Por foco'!$R$2:$R$579,'Por foco'!$A$2:$A$579,$A12) -> 0 | Q12: =SUMIFS('Por foco'!$S$2:$S$579,'Por foco'!$A$2:$A$579,$A12) -> 0 | R12: =SUMIFS('Por foco'!$T$2:$T$579,'Por foco'!$A$2:$A$579,$A12) -> 32150 | S12: =SUMIFS('Por foco'!$U$2:$U$579,'Por foco'!$A$2:$A$579,$A12) -> 8 | T12: =SUMIFS('Por foco'!$V$2:$V$579,'Por foco'!$A$2:$A$579,$A12) -> 0 | U12: =SUMIFS('Por foco'!$W$2:$W$579,'Por foco'!$A$2:$A$579,$A12) -> 0 | V12: =SUMIFS('Por foco'!$X$2:$X$579,'Por foco'!$A$2:$A$579,$A12) -> 7 | W12: =C12*Pesos!$B$2+D12*Pesos!$B$3+E12*Pesos!$B$4+F12*Pesos!$B$5+G12*Pesos!$B$6+H12*Pesos!$B$7+I12*Pesos!$B$8+J12*Pesos!$B$9+K12*Pesos!$B$10+L12*Pesos!$B$11+M12*Pesos!$B$12+N12*Pesos!$B$13+O12*Pesos!$B$14+P12*Pesos!$B$15+Q12*Pesos!$B$16+R12*Pesos!$B$17+S12*Pesos!$B$18+T12*Pesos!$B$19+U12*Pesos!$B$20+V12*Pesos!$B$21 -> 4643 | X12: =Espíritus!M35 -> 3985 | Y12: =W12+X12 -> 8628 | Z12: =IF($Y$16=0,0,Y12/$Y$16-1) -> -0.22706353 | AA12: =COUNTIFS('Por foco'!$A$2:$A$579,$A12,'Por foco'!$AA$2:$AA$579,"?*") -> 0
A13: ZWM | B13: =COUNTIF('Por foco'!$A$2:$A$579,$A13) -> 7 | C13: =SUMIFS('Por foco'!$E$2:$E$579,'Por foco'!$A$2:$A$579,$A13) -> 245 | D13: =SUMIFS('Por foco'!$F$2:$F$579,'Por foco'!$A$2:$A$579,$A13) -> 0 | E13: =SUMIFS('Por foco'!$G$2:$G$579,'Por foco'!$A$2:$A$579,$A13) -> 0 | F13: =SUMIFS('Por foco'!$H$2:$H$579,'Por foco'!$A$2:$A$579,$A13) -> 0 | G13: =SUMIFS('Por foco'!$I$2:$I$579,'Por foco'!$A$2:$A$579,$A13) -> 1240000 | H13: =SUMIFS('Por foco'!$J$2:$J$579,'Por foco'!$A$2:$A$579,$A13) -> 0 | I13: =SUMIFS('Por foco'!$K$2:$K$579,'Por foco'!$A$2:$A$579,$A13) -> 0 | J13: =SUMIFS('Por foco'!$L$2:$L$579,'Por foco'!$A$2:$A$579,$A13) -> 0 | K13: =SUMIFS('Por foco'!$M$2:$M$579,'Por foco'!$A$2:$A$579,$A13) -> 0 | L13: =SUMIFS('Por foco'!$N$2:$N$579,'Por foco'!$A$2:$A$579,$A13) -> 0 | M13: =SUMIFS('Por foco'!$O$2:$O$579,'Por foco'!$A$2:$A$579,$A13) -> 0 | N13: =SUMIFS('Por foco'!$P$2:$P$579,'Por foco'!$A$2:$A$579,$A13) -> 0 | O13: =SUMIFS('Por foco'!$Q$2:$Q$579,'Por foco'!$A$2:$A$579,$A13) -> 0 | P13: =SUMIFS('Por foco'!$R$2:$R$579,'Por foco'!$A$2:$A$579,$A13) -> 0 | Q13: =SUMIFS('Por foco'!$S$2:$S$579,'Por foco'!$A$2:$A$579,$A13) -> 0 | R13: =SUMIFS('Por foco'!$T$2:$T$579,'Por foco'!$A$2:$A$579,$A13) -> 32150 | S13: =SUMIFS('Por foco'!$U$2:$U$579,'Por foco'!$A$2:$A$579,$A13) -> 8 | T13: =SUMIFS('Por foco'!$V$2:$V$579,'Por foco'!$A$2:$A$579,$A13) -> 0 | U13: =SUMIFS('Por foco'!$W$2:$W$579,'Por foco'!$A$2:$A$579,$A13) -> 0 | V13: =SUMIFS('Por foco'!$X$2:$X$579,'Por foco'!$A$2:$A$579,$A13) -> 7 | W13: =C13*Pesos!$B$2+D13*Pesos!$B$3+E13*Pesos!$B$4+F13*Pesos!$B$5+G13*Pesos!$B$6+H13*Pesos!$B$7+I13*Pesos!$B$8+J13*Pesos!$B$9+K13*Pesos!$B$10+L13*Pesos!$B$11+M13*Pesos!$B$12+N13*Pesos!$B$13+O13*Pesos!$B$14+P13*Pesos!$B$15+Q13*Pesos!$B$16+R13*Pesos!$B$17+S13*Pesos!$B$18+T13*Pesos!$B$19+U13*Pesos!$B$20+V13*Pesos!$B$21 -> 3443 | X13: =Espíritus!N35 -> 3664 | Y13: =W13+X13 -> 7107 | Z13: =IF($Y$16=0,0,Y13/$Y$16-1) -> -0.3633218 | AA13: =COUNTIFS('Por foco'!$A$2:$A$579,$A13,'Por foco'!$AA$2:$AA$579,"?*") -> 0
A14: ZAN | B14: =COUNTIF('Por foco'!$A$2:$A$579,$A14) -> 7 | C14: =SUMIFS('Por foco'!$E$2:$E$579,'Por foco'!$A$2:$A$579,$A14) -> 2548 | D14: =SUMIFS('Por foco'!$F$2:$F$579,'Por foco'!$A$2:$A$579,$A14) -> 400 | E14: =SUMIFS('Por foco'!$G$2:$G$579,'Por foco'!$A$2:$A$579,$A14) -> 10 | F14: =SUMIFS('Por foco'!$H$2:$H$579,'Por foco'!$A$2:$A$579,$A14) -> 10 | G14: =SUMIFS('Por foco'!$I$2:$I$579,'Por foco'!$A$2:$A$579,$A14) -> 1950000 | H14: =SUMIFS('Por foco'!$J$2:$J$579,'Por foco'!$A$2:$A$579,$A14) -> 0 | I14: =SUMIFS('Por foco'!$K$2:$K$579,'Por foco'!$A$2:$A$579,$A14) -> 0 | J14: =SUMIFS('Por foco'!$L$2:$L$579,'Por foco'!$A$2:$A$579,$A14) -> 0 | K14: =SUMIFS('Por foco'!$M$2:$M$579,'Por foco'!$A$2:$A$579,$A14) -> 0 | L14: =SUMIFS('Por foco'!$N$2:$N$579,'Por foco'!$A$2:$A$579,$A14) -> 0 | M14: =SUMIFS('Por foco'!$O$2:$O$579,'Por foco'!$A$2:$A$579,$A14) -> 15 | N14: =SUMIFS('Por foco'!$P$2:$P$579,'Por foco'!$A$2:$A$579,$A14) -> 0 | O14: =SUMIFS('Por foco'!$Q$2:$Q$579,'Por foco'!$A$2:$A$579,$A14) -> 0 | P14: =SUMIFS('Por foco'!$R$2:$R$579,'Por foco'!$A$2:$A$579,$A14) -> 1 | Q14: =SUMIFS('Por foco'!$S$2:$S$579,'Por foco'!$A$2:$A$579,$A14) -> 0 | R14: =SUMIFS('Por foco'!$T$2:$T$579,'Por foco'!$A$2:$A$579,$A14) -> 38910 | S14: =SUMIFS('Por foco'!$U$2:$U$579,'Por foco'!$A$2:$A$579,$A14) -> 10 | T14: =SUMIFS('Por foco'!$V$2:$V$579,'Por foco'!$A$2:$A$579,$A14) -> 0 | U14: =SUMIFS('Por foco'!$W$2:$W$579,'Por foco'!$A$2:$A$579,$A14) -> 9 | V14: =SUMIFS('Por foco'!$X$2:$X$579,'Por foco'!$A$2:$A$579,$A14) -> 3 | W14: =C14*Pesos!$B$2+D14*Pesos!$B$3+E14*Pesos!$B$4+F14*Pesos!$B$5+G14*Pesos!$B$6+H14*Pesos!$B$7+I14*Pesos!$B$8+J14*Pesos!$B$9+K14*Pesos!$B$10+L14*Pesos!$B$11+M14*Pesos!$B$12+N14*Pesos!$B$13+O14*Pesos!$B$14+P14*Pesos!$B$15+Q14*Pesos!$B$16+R14*Pesos!$B$17+S14*Pesos!$B$18+T14*Pesos!$B$19+U14*Pesos!$B$20+V14*Pesos!$B$21 -> 7353.2 | X14: =Espíritus!O35 -> 750 | Y14: =W14+X14 -> 8103.2 | Z14: =IF($Y$16=0,0,Y14/$Y$16-1) -> -0.27407756 | AA14: =COUNTIFS('Por foco'!$A$2:$A$579,$A14,'Por foco'!$AA$2:$AA$579,"?*") -> 0
A15: JUNTA | B15: =COUNTIF('Por foco'!$A$2:$A$579,$A15) -> 11 | C15: =SUMIFS('Por foco'!$E$2:$E$579,'Por foco'!$A$2:$A$579,$A15) -> 420 | D15: =SUMIFS('Por foco'!$F$2:$F$579,'Por foco'!$A$2:$A$579,$A15) -> 0 | E15: =SUMIFS('Por foco'!$G$2:$G$579,'Por foco'!$A$2:$A$579,$A15) -> 0 | F15: =SUMIFS('Por foco'!$H$2:$H$579,'Por foco'!$A$2:$A$579,$A15) -> 0 | G15: =SUMIFS('Por foco'!$I$2:$I$579,'Por foco'!$A$2:$A$579,$A15) -> 800000 | H15: =SUMIFS('Por foco'!$J$2:$J$579,'Por foco'!$A$2:$A$579,$A15) -> 30 | I15: =SUMIFS('Por foco'!$K$2:$K$579,'Por foco'!$A$2:$A$579,$A15) -> 0 | J15: =SUMIFS('Por foco'!$L$2:$L$579,'Por foco'!$A$2:$A$579,$A15) -> 0 | K15: =SUMIFS('Por foco'!$M$2:$M$579,'Por foco'!$A$2:$A$579,$A15) -> 0 | L15: =SUMIFS('Por foco'!$N$2:$N$579,'Por foco'!$A$2:$A$579,$A15) -> 0 | M15: =SUMIFS('Por foco'!$O$2:$O$579,'Por foco'!$A$2:$A$579,$A15) -> 0 | N15: =SUMIFS('Por foco'!$P$2:$P$579,'Por foco'!$A$2:$A$579,$A15) -> 0 | O15: =SUMIFS('Por foco'!$Q$2:$Q$579,'Por foco'!$A$2:$A$579,$A15) -> 0 | P15: =SUMIFS('Por foco'!$R$2:$R$579,'Por foco'!$A$2:$A$579,$A15) -> 0 | Q15: =SUMIFS('Por foco'!$S$2:$S$579,'Por foco'!$A$2:$A$579,$A15) -> 0 | R15: =SUMIFS('Por foco'!$T$2:$T$579,'Por foco'!$A$2:$A$579,$A15) -> 100000 | S15: =SUMIFS('Por foco'!$U$2:$U$579,'Por foco'!$A$2:$A$579,$A15) -> 49 | T15: =SUMIFS('Por foco'!$V$2:$V$579,'Por foco'!$A$2:$A$579,$A15) -> 0 | U15: =SUMIFS('Por foco'!$W$2:$W$579,'Por foco'!$A$2:$A$579,$A15) -> 0 | V15: =SUMIFS('Por foco'!$X$2:$X$579,'Por foco'!$A$2:$A$579,$A15) -> 10 | W15: =C15*Pesos!$B$2+D15*Pesos!$B$3+E15*Pesos!$B$4+F15*Pesos!$B$5+G15*Pesos!$B$6+H15*Pesos!$B$7+I15*Pesos!$B$8+J15*Pesos!$B$9+K15*Pesos!$B$10+L15*Pesos!$B$11+M15*Pesos!$B$12+N15*Pesos!$B$13+O15*Pesos!$B$14+P15*Pesos!$B$15+Q15*Pesos!$B$16+R15*Pesos!$B$17+S15*Pesos!$B$18+T15*Pesos!$B$19+U15*Pesos!$B$20+V15*Pesos!$B$21 -> 5590 | X15: =Espíritus!P35 -> 1335 | Y15: =W15+X15 -> 6925 | Z15: =IF($Y$16=0,0,Y15/$Y$16-1) -> -0.37962621 | AA15: =COUNTIFS('Por foco'!$A$2:$A$579,$A15,'Por foco'!$AA$2:$AA$579,"?*") -> 0
A16: Promedio de las 8 potencias | B16: =AVERAGE(B2:B9) -> 66.5 | C16: =AVERAGE(C2:C9) -> 4310.25 | D16: =AVERAGE(D2:D9) -> 1307.5 | E16: =AVERAGE(E2:E9) -> 14.75 | F16: =AVERAGE(F2:F9) -> 18.125 | G16: =AVERAGE(G2:G9) -> 194375 | H16: =AVERAGE(H2:H9) -> 218.75 | I16: =AVERAGE(I2:I9) -> 50.625 | ... Y16: =AVERAGE(Y2:Y9) -> 11162.625

Sheet Por rama
A1: Árbol | B1: Rama | C1: Focos | D1: Días | E1: Poder político | F1: Estabilidad (%) | G1: Apoyo a la guerra (%) | H1: Mano de obra | I1: Exp. ejército | J1: Exp. naval | K1: Exp. aérea | L1: Casillas de investigación | M1: Bonos de tecnología (usos) | N1: Fábricas civiles | O1: Fábricas militares | P1: Astilleros | Q1: Infraestructura | R1: Otros edificios (niveles) | S1: Equipo (unidades) | T1: Divisiones | U1: Cazas gratis | V1: Reclamos, núcleos y objetivos | W1: Espíritus (agregados)
A2: EFE | B2: dinastia_verde | C2: =COUNTIFS('Por foco'!$A$2:$A$579,$A2,'Por foco'!$B$2:$B$579,$B2) -> 11 | D2: =SUMIFS('Por foco'!$E$2:$E$579,'Por foco'!$A$2:$A$579,$A2,'Por foco'!$B$2:$B$579,$B2) -> 707 | E2: =SUMIFS('Por foco'!$F$2:$F$579,'Por foco'!$A$2:$A$579,$A2,'Por foco'!$B$2:$B$579,$B2) -> 600 | F2: =SUMIFS('Por foco'!$G$2:$G$579,'Por foco'!$A$2:$A$579,$A2,'Por foco'!$B$2:$B$579,$B2) -> 0 | G2: =SUMIFS('Por foco'!$H$2:$H$579,'Por foco'!$A$2:$A$579,$A2,'Por foco'!$B$2:$B$579,$B2) -> 5 | H2: =SUMIFS('Por foco'!$I$2:$I$579,'Por foco'!$A$2:$A$579,$A2,'Por foco'!$B$2:$B$579,$B2) -> 0 | I2: =SUMIFS('Por foco'!$J$2:$J$579,'Por foco'!$A$2:$A$579,$A2,'Por foco'!$B$2:$B$579,$B2) -> 0 | J2: =SUMIFS('Por foco'!$K$2:$K$579,'Por foco'!$A$2:$A$579,$A2,'Por foco'!$B$2:$B$579,$B2) -> 0 | K2: =SUMIFS('Por foco'!$L$2:$L$579,'Por foco'!$A$2:$A$579,$A2,'Por foco'!$B$2:$B$579,$B2) -> 0 | L2: =SUMIFS('Por foco'!$M$2:$M$579,'Por foco'!$A$2:$A$579,$A2,'Por foco'!$B$2:$B$579,$B2) -> 0 | M2: =SUMIFS('Por foco'!$N$2:$N$579,'Por foco'!$A$2:$A$579,$A2,'Por foco'!$B$2:$B$579,$B2) -> 0 | N2: =SUMIFS('Por foco'!$O$2:$O$579,'Por foco'!$A$2:$A$579,$A2,'Por foco'!$B$2:$B$579,$B2) -> 0 | O2: =SUMIFS('Por foco'!$P$2:$P$579,'Por foco'!$A$2:$A$579,$A2,'Por foco'!$B$2:$B$579,$B2) -> 0 | P2: =SUMIFS('Por foco'!$Q$2:$Q$579,'Por foco'!$A$2:$A$579,$A2,'Por foco'!$B$2:$B$579,$B2) -> 0 | Q2: =SUMIFS('Por foco'!$R$2:$R$579,'Por foco'!$A$2:$A$579,$A2,'Por foco'!$B$2:$B$579,$B2) -> 0 | R2: =SUMIFS('Por foco'!$S$2:$S$579,'Por foco'!$A$2:$A$579,$A2,'Por foco'!$B$2:$B$579,$B2) -> 0 | S2: =SUMIFS('Por foco'!$T$2:$T$579,'Por foco'!$A$2:$A$579,$A2,'Por foco'!$B$2:$B$579,$B2) -> 0 | T2: =SUMIFS('Por foco'!$U$2:$U$579,'Por foco'!$A$2:$A$579,$A2,'Por foco'!$B$2:$B$579,$B2) -> 0 | U2: =SUMIFS('Por foco'!$V$2:$V$579,'Por foco'!$A$2:$A$579,$A2,'Por foco'!$B$2:$B$579,$B2) -> 0 | V2: =SUMIFS('Por foco'!$W$2:$W$579,'Por foco'!$A$2:$A$579,$A2,'Por foco'!$B$2:$B$579,$B2) -> 2 | W2: =SUMIFS('Por foco'!$X$2:$X$579,'Por foco'!$A$2:$A$579,$A2,'Por foco'!$B$2:$B$579,$B2) -> 4
A3: EFE | B3: el_monte | C3: =COUNTIFS('Por foco'!$A$2:$A$579,$A3,'Por foco'!$B$2:$B$579,$B3) -> 9 | D3: =SUMIFS('Por foco'!$E$2:$E$579,'Por foco'!$A$2:$A$579,$A3,'Por foco'!$B$2:$B$579,$B3) -> 539 | E3: =SUMIFS('Por foco'!$F$2:$F$579,'Por foco'!$A$2:$A$579,$A3,'Por foco'!$B$2:$B$579,$B3) -> 0 | F3: =SUMIFS('Por foco'!$G$2:$G$579,'Por foco'!$A$2:$A$579,$A3,'Por foco'!$B$2:$B$579,$B3) -> 0 | G3: =SUMIFS('Por foco'!$H$2:$H$579,'Por foco'!$A$2:$A$579,$A3,'Por foco'!$B$2:$B$579,$B3) -> 0 | H3: =SUMIFS('Por foco'!$I$2:$I$579,'Por foco'!$A$2:$A$579,$A3,'Por foco'!$B$2:$B$579,$B3) -> 30000 | I3: =SUMIFS('Por foco'!$J$2:$J$579,'Por foco'!$A$2:$A$579,$A3,'Por foco'!$B$2:$B$579,$B3) -> 0 | J3: =SUMIFS('Por foco'!$K$2:$K$579,'Por foco'!$A$2:$A$579,$A3,'Por foco'!$B$2:$B$579,$B3) -> 0 | K3: =SUMIFS('Por foco'!$L$2:$L$579,'Por foco'!$A$2:$A$579,$A3,'Por foco'!$B$2:$B$579,$B3) -> 0 | L3: =SUMIFS('Por foco'!$M$2:$M$579,'Por foco'!$A$2:$A$579,$A3,'Por foco'!$B$2:$B$579,$B3) -> 0 | M3: =SUMIFS('Por foco'!$N$2:$N$579,'Por foco'!$A$2:$A$579,$A3,'Por foco'!$B$2:$B$579,$B3) -> 2 | N3: =SUMIFS('Por foco'!$O$2:$O$579,'Por foco'!$A$2:$A$579,$A3,'Por foco'!$B$2:$B$579,$B3) -> 0 | O3: =SUMIFS('Por foco'!$P$2:$P$579,'Por foco'!$A$2:$A$579,$A3,'Por foco'!$B$2:$B$579,$B3) -> 3 | P3: =SUMIFS('Por foco'!$Q$2:$Q$579,'Por foco'!$A$2:$A$579,$A3,'Por foco'!$B$2:$B$579,$B3) -> 0 | Q3: =SUMIFS('Por foco'!$R$2:$R$579,'Por foco'!$A$2:$A$579,$A3,'Por foco'!$B$2:$B$579,$B3) -> 0 | R3: =SUMIFS('Por foco'!$S$2:$S$579,'Por foco'!$A$2:$A$579,$A3,'Por foco'!$B$2:$B$579,$B3) -> 0 | S3: =SUMIFS('Por foco'!$T$2:$T$579,'Por foco'!$A$2:$A$579,$A3,'Por foco'!$B$2:$B$579,$B3) -> 0 | T3: =SUMIFS('Por foco'!$U$2:$U$579,'Por foco'!$A$2:$A$579,$A3,'Por foco'!$B$2:$B$579,$B3) -> 0 | U3: =SUMIFS('Por foco'!$V$2:$V$579,'Por foco'!$A$2:$A$579,$A3,'Por foco'!$B$2:$B$579,$B3) -> 0 | V3: =SUMIFS('Por foco'!$W$2:$W$579,'Por foco'!$A$2:$A$579,$A3,'Por foco'!$B$2:$B$579,$B3) -> 1 | W3: =SUMIFS('Por foco'!$X$2:$X$579,'Por foco'!$A$2:$A$579,$A3,'Por foco'!$B$2:$B$579,$B3) -> 8
A4: EFE | B4: destino | C4: =COUNTIFS('Por foco'!$A$2:$A$579,$A4,'Por foco'!$B$2:$B$579,$B4) -> 4 | D4: =SUMIFS('Por foco'!$E$2:$E$579,'Por foco'!$A$2:$A$579,$A4,'Por foco'!$B$2:$B$579,$B4) -> 315 | E4: =SUMIFS('Por foco'!$F$2:$F$579,'Por foco'!$A$2:$A$579,$A4,'Por foco'!$B$2:$B$579,$B4) -> 170 | F4: =SUMIFS('Por foco'!$G$2:$G$579,'Por foco'!$A$2:$A$579,$A4,'Por foco'!$B$2:$B$579,$B4) -> 5 | G4: =SUMIFS('Por foco'!$H$2:$H$579,'Por foco'!$A$2:$A$579,$A4,'Por foco'!$B$2:$B$579,$B4) -> 5 | H4: =SUMIFS('Por foco'!$I$2:$I$579,'Por foco'!$A$2:$A$579,$A4,'Por foco'!$B$2:$B$579,$B4) -> 0 | I4: =SUMIFS('Por foco'!$J$2:$J$579,'Por foco'!$A$2:$A$579,$A4,'Por foco'!$B$2:$B$579,$B4) -> 25 | J4: =SUMIFS('Por foco'!$K$2:$K$579,'Por foco'!$A$2:$A$579,$A4,'Por foco'!$B$2:$B$579,$B4) -> 0 | K4: =SUMIFS('Por foco'!$L$2:$L$579,'Por foco'!$A$2:$A$579,$A4,'Por foco'!$B$2:$B$579,$B4) -> 0 | L4: =SUMIFS('Por foco'!$M$2:$M$579,'Por foco'!$A$2:$A$579,$A4,'Por foco'!$B$2:$B$579,$B4) -> 0 | M4: =SUMIFS('Por foco'!$N$2:$N$579,'Por foco'!$A$2:$A$579,$A4,'Por foco'!$B$2:$B$579,$B4) -> 0 | N4: =SUMIFS('Por foco'!$O$2:$O$579,'Por foco'!$A$2:$A$579,$A4,'Por foco'!$B$2:$B$579,$B4) -> 0 | O4: =SUMIFS('Por foco'!$P$2:$P$579,'Por foco'!$A$2:$A$579,$A4,'Por foco'!$B$2:$B$579,$B4) -> 0 | P4: =SUMIFS('Por foco'!$Q$2:$Q$579,'Por foco'!$A$2:$A$579,$A4,'Por foco'!$B$2:$B$579,$B4) -> 0 | Q4: =SUMIFS('Por foco'!$R$2:$R$579,'Por foco'!$A$2:$A$579,$A4,'Por foco'!$B$2:$B$579,$B4) -> 0 | R4: =SUMIFS('Por foco'!$S$2:$S$579,'Por foco'!$A$2:$A$579,$A4,'Por foco'!$B$2:$B$579,$B4) -> 0 | S4: =SUMIFS('Por foco'!$T$2:$T$579,'Por foco'!$A$2:$A$579,$A4,'Por foco'!$B$2:$B$579,$B4) -> 0 | T4: =SUMIFS('Por foco'!$U$2:$U$579,'Por foco'!$A$2:$A$579,$A4,'Por foco'!$B$2:$B$579,$B4) -> 0 | U4: =SUMIFS('Por foco'!$V$2:$V$579,'Por foco'!$A$2:$A$579,$A4,'Por foco'!$B$2:$B$579,$B4) -> 0 | V4: =SUMIFS('Por foco'!$W$2:$W$579,'Por foco'!$A$2:$A$579,$A4,'Por foco'!$B$2:$B$579,$B4) -> 8 | W4: =SUMIFS('Por foco'!$X$2:$X$579,'Por foco'!$A$2:$A$579,$A4,'Por foco'!$B$2:$B$579,$B4) -> 1
A5: EFE | B5: autarquia | C5: =COUNTIFS('Por foco'!$A$2:$A$579,$A5,'Por foco'!$B$2:$B$579,$B5) -> 8 | D5: =SUMIFS('Por foco'!$E$2:$E$579,'Por foco'!$A$2:$A$579,$A5,'Por foco'!$B$2:$B$579,$B5) -> 532 | E5: =SUMIFS('Por foco'!$F$2:$F$579,'Por foco'!$A$2:$A$579,$A5,'Por foco'!$B$2:$B$579,$B5) -> 250 | F5: =SUMIFS('Por foco'!$G$2:$G$579,'Por foco'!$A$2:$A$579,$A5,'Por foco'!$B$2:$B$579,$B5) -> -5 | G5: =SUMIFS('Por foco'!$H$2:$H$579,'Por foco'!$A$2:$A$579,$A5,'Por foco'!$B$2:$B$579,$B5) -> 0 | H5: =SUMIFS('Por foco'!$I$2:$I$579,'Por foco'!$A$2:$A$579,$A5,'Por foco'!$B$2:$B$579,$B5) -> 0 | I5: =SUMIFS('Por foco'!$J$2:$J$579,'Por foco'!$A$2:$A$579,$A5,'Por foco'!$B$2:$B$579,$B5) -> 0 | J5: =SUMIFS('Por foco'!$K$2:$K$579,'Por foco'!$A$2:$A$579,$A5,'Por foco'!$B$2:$B$579,$B5) -> 0 | K5: =SUMIFS('Por foco'!$L$2:$L$579,'Por foco'!$A$2:$A$579,$A5,'Por foco'!$B$2:$B$579,$B5) -> 0 | L5: =SUMIFS('Por foco'!$M$2:$M$579,'Por foco'!$A$2:$A$579,$A5,'Por foco'!$B$2:$B$579,$B5) -> 0 | M5: =SUMIFS('Por foco'!$N$2:$N$579,'Por foco'!$A$2:$A$579,$A5,'Por foco'!$B$2:$B$579,$B5) -> 2 | N5: =SUMIFS('Por foco'!$O$2:$O$579,'Por foco'!$A$2:$A$579,$A5,'Por foco'!$B$2:$B$579,$B5) -> 5 | O5: =SUMIFS('Por foco'!$P$2:$P$579,'Por foco'!$A$2:$A$579,$A5,'Por foco'!$B$2:$B$579,$B5) -> 2 | P5: =SUMIFS('Por foco'!$Q$2:$Q$579,'Por foco'!$A$2:$A$579,$A5,'Por foco'!$B$2:$B$579,$B5) -> 0 | Q5: =SUMIFS('Por foco'!$R$2:$R$579,'Por foco'!$A$2:$A$579,$A5,'Por foco'!$B$2:$B$579,$B5) -> 0 | R5: =SUMIFS('Por foco'!$S$2:$S$579,'Por foco'!$A$2:$A$579,$A5,'Por foco'!$B$2:$B$579,$B5) -> 0 | S5: =SUMIFS('Por foco'!$T$2:$T$579,'Por foco'!$A$2:$A$579,$A5,'Por foco'!$B$2:$B$579,$B5) -> 0 | T5: =SUMIFS('Por foco'!$U$2:$U$579,'Por foco'!$A$2:$A$579,$A5,'Por foco'!$B$2:$B$579,$B5) -> 0 | U5: =SUMIFS('Por foco'!$V$2:$V$579,'Por foco'!$A$2:$A$579,$A5,'Por foco'!$B$2:$B$579,$B5) -> 0 | V5: =SUMIFS('Por foco'!$W$2:$W$579,'Por foco'!$A$2:$A$579,$A5,'Por foco'!$B$2:$B$579,$B5) -> 0 | W5: =SUMIFS('Por foco'!$X$2:$X$579,'Por foco'!$A$2:$A$579,$A5,'Por foco'!$B$2:$B$579,$B5) -> 3
A6: EFE | B6: diplomacia_agua | C6: =COUNTIFS('Por foco'!$A$2:$A$579,$A6,'Por foco'!$B$2:$B$579,$B6) -> 7 | D6: =SUMIFS('Por foco'!$E$2:$E$579,'Por foco'!$A$2:$A$579,$A6,'Por foco'!$B$2:$B$579,$B6) -> 483 | E6: =SUMIFS('Por foco'!$F$2:$F$579,'Por foco'!$A$2:$A$579,$A6,'Por foco'!$B$2:$B$579,$B6) -> 200 | F6: =SUMIFS('Por foco'!$G$2:$G$579,'Por foco'!$A$2:$A$579,$A6,'Por foco'!$B$2:$B$579,$B6) -> 0 | G6: =SUMIFS('Por foco'!$H$2:$H$579,'Por foco'!$A$2:$A$579,$A6,'Por foco'!$B$2:$B$579,$B6) -> 0 | H6: =SUMIFS('Por foco'!$I$2:$I$579,'Por foco'!$A$2:$A$579,$A6,'Por foco'!$B$2:$B$579,$B6) -> 0 | I6: =SUMIFS('Por foco'!$J$2:$J$579,'Por foco'!$A$2:$A$579,$A6,'Por foco'!$B$2:$B$579,$B6) -> 0 | J6: =SUMIFS('Por foco'!$K$2:$K$579,'Por foco'!$A$2:$A$579,$A6,'Por foco'!$B$2:$B$579,$B6) -> 0 | K6: =SUMIFS('Por foco'!$L$2:$L$579,'Por foco'!$A$2:$A$579,$A6,'Por foco'!$B$2:$B$579,$B6) -> 0 | L6: =SUMIFS('Por foco'!$M$2:$M$579,'Por foco'!$A$2:$A$579,$A6,'Por foco'!$B$2:$B$579,$B6) -> 0 | M6: =SUMIFS('Por foco'!$N$2:$N$579,'Por foco'!$A$2:$A$579,$A6,'Por foco'!$B$2:$B$579,$B6) -> 0 | N6: =SUMIFS('Por foco'!$O$2:$O$579,'Por foco'!$A$2:$A$579,$A6,'Por foco'!$B$2:$B$579,$B6) -> 6 | O6: =SUMIFS('Por foco'!$P$2:$P$579,'Por foco'!$A$2:$A$579,$A6,'Por foco'!$B$2:$B$579,$B6) -> 0 | P6: =SUMIFS('Por foco'!$Q$2:$Q$579,'Por foco'!$A$2:$A$579,$A6,'Por foco'!$B$2:$B$579,$B6) -> 0 | Q6: =SUMIFS('Por foco'!$R$2:$R$579,'Por foco'!$A$2:$A$579,$A6,'Por foco'!$B$2:$B$579,$B6) -> 0 | R6: =SUMIFS('Por foco'!$S$2:$S$579,'Por foco'!$A$2:$A$579,$A6,'Por foco'!$B$2:$B$579,$B6) -> 0 | S6: =SUMIFS('Por foco'!$T$2:$T$579,'Por foco'!$A$2:$A$579,$A6,'Por foco'!$B$2:$B$579,$B6) -> 0 | T6: =SUMIFS('Por foco'!$U$2:$U$579,'Por foco'!$A$2:$A$579,$A6,'Por foco'!$B$2:$B$579,$B6) -> 0 | U6: =SUMIFS('Por foco'!$V$2:$V$579,'Por foco'!$A$2:$A$579,$A6,'Por foco'!$B$2:$B$579,$B6) -> 0 | V6: =SUMIFS('Por foco'!$W$2:$W$579,'Por foco'!$A$2:$A$579,$A6,'Por foco'!$B$2:$B$579,$B6) -> 0 | W6: =SUMIFS('Por foco'!$X$2:$X$579,'Por foco'!$A$2:$A$579,$A6,'Por foco'!$B$2:$B$579,$B6) -> 3
A7: EFE | B7: cubas | C7: =COUNTIFS('Por foco'!$A$2:$A$579,$A7,'Por foco'!$B$2:$B$579,$B7) -> 6 | D7: =SUMIFS('Por foco'!$E$2:$E$579,'Por foco'!$A$2:$A$579,$A7,'Por foco'!$B$2:$B$579,$B7) -> 364 | E7: =SUMIFS('Por foco'!$F$2:$F$579,'Por foco'!$A$2:$A$579,$A7,'Por foco'!$B$2:$B$579,$B7) -> 0 | F7: =SUMIFS('Por foco'!$G$2:$G$579,'Por foco'!$A$2:$A$579,$A7,'Por foco'!$B$2:$B$579,$B7) -> 0 | G7: =SUMIFS('Por foco'!$H$2:$H$579,'Por foco'!$A$2:$A$579,$A7,'Por foco'!$B$2:$B$579,$B7) -> 0 | H7: =SUMIFS('Por foco'!$I$2:$I$579,'Por foco'!$A$2:$A$579,$A7,'Por foco'!$B$2:$B$579,$B7) -> 0 | I7: =SUMIFS('Por foco'!$J$2:$J$579,'Por foco'!$A$2:$A$579,$A7,'Por foco'!$B$2:$B$579,$B7) -> 0 | J7: =SUMIFS('Por foco'!$K$2:$K$579,'Por foco'!$A$2:$A$579,$A7,'Por foco'!$B$2:$B$579,$B7) -> 0 | K7: =SUMIFS('Por foco'!$L$2:$L$579,'Por foco'!$A$2:$A$579,$A7,'Por foco'!$B$2:$B$579,$B7) -> 0 | L7: =SUMIFS('Por foco'!$M$2:$M$579,'Por foco'!$A$2:$A$579,$A7,'Por foco'!$B$2:$B$579,$B7) -> 1 | M7: =SUMIFS('Por foco'!$N$2:$N$579,'Por foco'!$A$2:$A$579,$A7,'Por foco'!$B$2:$B$579,$B7) -> 1 | N7: =SUMIFS('Por foco'!$O$2:$O$579,'Por foco'!$A$2:$A$579,$A7,'Por foco'!$B$2:$B$579,$B7) -> 4 | O7: =SUMIFS('Por foco'!$P$2:$P$579,'Por foco'!$A$2:$A$579,$A7,'Por foco'!$B$2:$B$579,$B7) -> 2 | P7: =SUMIFS('Por foco'!$Q$2:$Q$579,'Por foco'!$A$2:$A$579,$A7,'Por foco'!$B$2:$B$579,$B7) -> 2 | Q7: =SUMIFS('Por foco'!$R$2:$R$579,'Por foco'!$A$2:$A$579,$A7,'Por foco'!$B$2:$B$579,$B7) -> 0 | R7: =SUMIFS('Por foco'!$S$2:$S$579,'Por foco'!$A$2:$A$579,$A7,'Por foco'!$B$2:$B$579,$B7) -> 0 | S7: =SUMIFS('Por foco'!$T$2:$T$579,'Por foco'!$A$2:$A$579,$A7,'Por foco'!$B$2:$B$579,$B7) -> 0 | T7: =SUMIFS('Por foco'!$U$2:$U$579,'Por foco'!$A$2:$A$579,$A7,'Por foco'!$B$2:$B$579,$B7) -> 0 | U7: =SUMIFS('Por foco'!$V$2:$V$579,'Por foco'!$A$2:$A$579,$A7,'Por foco'!$B$2:$B$579,$B7) -> 0 | V7: =SUMIFS('Por foco'!$W$2:$W$579,'Por foco'!$A$2:$A$579,$A7,'Por foco'!$B$2:$B$579,$B7) -> 0 | W7: =SUMIFS('Por foco'!$X$2:$X$579,'Por foco'!$A$2:$A$579,$A7,'Por foco'!$B$2:$B$579,$B7) -> 1
A8: EFE | B8: guardia_verde | C8: =COUNTIFS('Por foco'!$A$2:$A$579,$A8,'Por foco'!$B$2:$B$579,$B8) -> 6 | D8: =SUMIFS('Por foco'!$E$2:$E$579,'Por foco'!$A$2:$A$579,$A8,'Por foco'!$B$2:$B$579,$B8) -> 343 | E8: =SUMIFS('Por foco'!$F$2:$F$579,'Por foco'!$A$2:$A$579,$A8,'Por foco'!$B$2:$B$579,$B8) -> 0 | F8: =SUMIFS('Por foco'!$G$2:$G$579,'Por foco'!$A$2:$A$579,$A8,'Por foco'!$B$2:$B$579,$B8) -> 0 | G8: =SUMIFS('Por foco'!$H$2:$H$579,'Por foco'!$A$2:$A$579,$A8,'Por foco'!$B$2:$B$579,$B8) -> 0 | H8: =SUMIFS('Por foco'!$I$2:$I$579,'Por foco'!$A$2:$A$579,$A8,'Por foco'!$B$2:$B$579,$B8) -> 50000 | I8: =SUMIFS('Por foco'!$J$2:$J$579,'Por foco'!$A$2:$A$579,$A8,'Por foco'!$B$2:$B$579,$B8) -> 75 | J8: =SUMIFS('Por foco'!$K$2:$K$579,'Por foco'!$A$2:$A$579,$A8,'Por foco'!$B$2:$B$579,$B8) -> 0 | K8: =SUMIFS('Por foco'!$L$2:$L$579,'Por foco'!$A$2:$A$579,$A8,'Por foco'!$B$2:$B$579,$B8) -> 0 | L8: =SUMIFS('Por foco'!$M$2:$M$579,'Por foco'!$A$2:$A$579,$A8,'Por foco'!$B$2:$B$579,$B8) -> 0 | M8: =SUMIFS('Por foco'!$N$2:$N$579,'Por foco'!$A$2:$A$579,$A8,'Por foco'!$B$2:$B$579,$B8) -> 4 | N8: =SUMIFS('Por foco'!$O$2:$O$579,'Por foco'!$A$2:$A$579,$A8,'Por foco'!$B$2:$B$579,$B8) -> 0 | O8: =SUMIFS('Por foco'!$P$2:$P$579,'Por foco'!$A$2:$A$579,$A8,'Por foco'!$B$2:$B$579,$B8) -> 0 | P8: =SUMIFS('Por foco'!$Q$2:$Q$579,'Por foco'!$A$2:$A$579,$A8,'Por foco'!$B$2:$B$579,$B8) -> 0 | Q8: =SUMIFS('Por foco'!$R$2:$R$579,'Por foco'!$A$2:$A$579,$A8,'Por foco'!$B$2:$B$579,$B8) -> 0 | R8: =SUMIFS('Por foco'!$S$2:$S$579,'Por foco'!$A$2:$A$579,$A8,'Por foco'!$B$2:$B$579,$B8) -> 0 | S8: =SUMIFS('Por foco'!$T$2:$T$579,'Por foco'!$A$2:$A$579,$A8,'Por foco'!$B$2:$B$579,$B8) -> 0 | T8: =SUMIFS('Por foco'!$U$2:$U$579,'Por foco'!$A$2:$A$579,$A8,'Por foco'!$B$2:$B$579,$B8) -> 0 | U8: =SUMIFS('Por foco'!$V$2:$V$579,'Por foco'!$A$2:$A$579,$A8,'Por foco'!$B$2:$B$579,$B8) -> 0 | V8: =SUMIFS('Por foco'!$W$2:$W$579,'Por foco'!$A$2:$A$579,$A8,'Por foco'!$B$2:$B$579,$B8) -> 0 | W8: =SUMIFS('Por foco'!$X$2:$X$579,'Por foco'!$A$2:$A$579,$A8,'Por foco'!$B$2:$B$579,$B8) -> 3
A9: EFE | B9: condores | C9: =COUNTIFS('Por foco'!$A$2:$A$579,$A9,'Por foco'!$B$2:$B$579,$B9) -> 6 | D9: =SUMIFS('Por foco'!$E$2:$E$579,'Por foco'!$A$2:$A$579,$A9,'Por foco'!$B$2:$B$579,$B9) -> 343 | E9: =SUMIFS('Por foco'!$F$2:$F$579,'Por foco'!$A$2:$A$579,$A9,'Por foco'!$B$2:$B$579,$B9) -> 0 | F9: =SUMIFS('Por foco'!$G$2:$G$579,'Por foco'!$A$2:$A$579,$A9,'Por foco'!$B$2:$B$579,$B9) -> 0 | G9: =SUMIFS('Por foco'!$H$2:$H$579,'Por foco'!$A$2:$A$579,$A9,'Por foco'!$B$2:$B$579,$B9) -> 5 | H9: =SUMIFS('Por foco'!$I$2:$I$579,'Por foco'!$A$2:$A$579,$A9,'Por foco'!$B$2:$B$579,$B9) -> 0 | I9: =SUMIFS('Por foco'!$J$2:$J$579,'Por foco'!$A$2:$A$579,$A9,'Por foco'!$B$2:$B$579,$B9) -> 0 | J9: =SUMIFS('Por foco'!$K$2:$K$579,'Por foco'!$A$2:$A$579,$A9,'Por foco'!$B$2:$B$579,$B9) -> 0 | K9: =SUMIFS('Por foco'!$L$2:$L$579,'Por foco'!$A$2:$A$579,$A9,'Por foco'!$B$2:$B$579,$B9) -> 75 | L9: =SUMIFS('Por foco'!$M$2:$M$579,'Por foco'!$A$2:$A$579,$A9,'Por foco'!$B$2:$B$579,$B9) -> 0 | M9: =SUMIFS('Por foco'!$N$2:$N$579,'Por foco'!$A$2:$A$579,$A9,'Por foco'!$B$2:$B$579,$B9) -> 5 | N9: =SUMIFS('Por foco'!$O$2:$O$579,'Por foco'!$A$2:$A$579,$A9,'Por foco'!$B$2:$B$579,$B9) -> 0 | O9: =SUMIFS('Por foco'!$P$2:$P$579,'Por foco'!$A$2:$A$579,$A9,'Por foco'!$B$2:$B$579,$B9) -> 0 | P9: =SUMIFS('Por foco'!$Q$2:$Q$579,'Por foco'!$A$2:$A$579,$A9,'Por foco'!$B$2:$B$579,$B9) -> 2 | Q9: =SUMIFS('Por foco'!$R$2:$R$579,'Por foco'!$A$2:$A$579,$A9,'Por foco'!$B$2:$B$579,$B9) -> 0 | R9: =SUMIFS('Por foco'!$S$2:$S$579,'Por foco'!$A$2:$A$579,$A9,'Por foco'!$B$2:$B$579,$B9) -> 2 | S9: =SUMIFS('Por foco'!$T$2:$T$579,'Por foco'!$A$2:$A$579,$A9,'Por foco'!$B$2:$B$579,$B9) -> 0 | T9: =SUMIFS('Por foco'!$U$2:$U$579,'Por foco'!$A$2:$A$579,$A9,'Por foco'!$B$2:$B$579,$B9) -> 0 | U9: =SUMIFS('Por foco'!$V$2:$V$579,'Por foco'!$A$2:$A$579,$A9,'Por foco'!$B$2:$B$579,$B9) -> 150 | V9: =SUMIFS('Por foco'!$W$2:$W$579,'Por foco'!$A$2:$A$579,$A9,'Por foco'!$B$2:$B$579,$B9) -> 0 | W9: =SUMIFS('Por foco'!$X$2:$X$579,'Por foco'!$A$2:$A$579,$A9,'Por foco'!$B$2:$B$579,$B9) -> 0
A10: EFE | B10: ciclo_bioacero | C10: =COUNTIFS('Por foco'!$A$2:$A$579,$A10,'Por foco'!$B$2:$B$579,$B10) -> 7 | D10: =SUMIFS('Por foco'!$E$2:$E$579,'Por foco'!$A$2:$A$579,$A10,'Por foco'!$B$2:$B$579,$B10) -> 448 | E10: =SUMIFS('Por foco'!$F$2:$F$579,'Por foco'!$A$2:$A$579,$A10,'Por foco'!$B$2:$B$579,$B10) -> 150 | F10: =SUMIFS('Por foco'!$G$2:$G$579,'Por foco'!$A$2:$A$579,$A10,'Por foco'!$B$2:$B$579,$B10) -> 0 | G10: =SUMIFS('Por foco'!$H$2:$H$579,'Por foco'!$A$2:$A$579,$A10,'Por foco'!$B$2:$B$579,$B10) -> 0 | H10: =SUMIFS('Por foco'!$I$2:$I$579,'Por foco'!$A$2:$A$579,$A10,'Por foco'!$B$2:$B$579,$B10) -> 0 | I10: =SUMIFS('Por foco'!$J$2:$J$579,'Por foco'!$A$2:$A$579,$A10,'Por foco'!$B$2:$B$579,$B10) -> 0 | J10: =SUMIFS('Por foco'!$K$2:$K$579,'Por foco'!$A$2:$A$579,$A10,'Por foco'!$B$2:$B$579,$B10) -> 0 | K10: =SUMIFS('Por foco'!$L$2:$L$579,'Por foco'!$A$2:$A$579,$A10,'Por foco'!$B$2:$B$579,$B10) -> 0 | L10: =SUMIFS('Por foco'!$M$2:$M$579,'Por foco'!$A$2:$A$579,$A10,'Por foco'!$B$2:$B$579,$B10) -> 1 | M10: =SUMIFS('Por foco'!$N$2:$N$579,'Por foco'!$A$2:$A$579,$A10,'Por foco'!$B$2:$B$579,$B10) -> 0 | N10: =SUMIFS('Por foco'!$O$2:$O$579,'Por foco'!$A$2:$A$579,$A10,'Por foco'!$B$2:$B$579,$B10) -> 0 | O10: =SUMIFS('Por foco'!$P$2:$P$579,'Por foco'!$A$2:$A$579,$A10,'Por foco'!$B$2:$B$579,$B10) -> 0 | P10: =SUMIFS('Por foco'!$Q$2:$Q$579,'Por foco'!$A$2:$A$579,$A10,'Por foco'!$B$2:$B$579,$B10) -> 0 | Q10: =SUMIFS('Por foco'!$R$2:$R$579,'Por foco'!$A$2:$A$579,$A10,'Por foco'!$B$2:$B$579,$B10) -> 0 | R10: =SUMIFS('Por foco'!$S$2:$S$579,'Por foco'!$A$2:$A$579,$A10,'Por foco'!$B$2:$B$579,$B10) -> 0 | S10: =SUMIFS('Por foco'!$T$2:$T$579,'Por foco'!$A$2:$A$579,$A10,'Por foco'!$B$2:$B$579,$B10) -> 0 | T10: =SUMIFS('Por foco'!$U$2:$U$579,'Por foco'!$A$2:$A$579,$A10,'Por foco'!$B$2:$B$579,$B10) -> 0 | U10: =SUMIFS('Por foco'!$V$2:$V$579,'Por foco'!$A$2:$A$579,$A10,'Por foco'!$B$2:$B$579,$B10) -> 0 | V10: =SUMIFS('Por foco'!$W$2:$W$579,'Por foco'!$A$2:$A$579,$A10,'Por foco'!$B$2:$B$579,$B10) -> 0 | W10: =SUMIFS('Por foco'!$X$2:$X$579,'Por foco'!$A$2:$A$579,$A10,'Por foco'!$B$2:$B$579,$B10) -> 3
A11: EFE | B11: cubas_sanas | C11: =COUNTIFS('Por foco'!$A$2:$A$579,$A11,'Por foco'!$B$2:$B$579,$B11) -> 6 | D11: =SUMIFS('Por foco'!$E$2:$E$579,'Por foco'!$A$2:$A$579,$A11,'Por foco'!$B$2:$B$579,$B11) -> 413 | E11: =SUMIFS('Por foco'!$F$2:$F$579,'Por foco'!$A$2:$A$579,$A11,'Por foco'!$B$2:$B$579,$B11) -> 100 | F11: =SUMIFS('Por foco'!$G$2:$G$579,'Por foco'!$A$2:$A$579,$A11,'Por foco'!$B$2:$B$579,$B11) -> 0 | G11: =SUMIFS('Por foco'!$H$2:$H$579,'Por foco'!$A$2:$A$579,$A11,'Por foco'!$B$2:$B$579,$B11) -> 0 | H11: =SUMIFS('Por foco'!$I$2:$I$579,'Por foco'!$A$2:$A$579,$A11,'Por foco'!$B$2:$B$579,$B11) -> 0 | I11: =SUMIFS('Por foco'!$J$2:$J$579,'Por foco'!$A$2:$A$579,$A11,'Por foco'!$B$2:$B$579,$B11) -> 0 | J11: =SUMIFS('Por foco'!$K$2:$K$579,'Por foco'!$A$2:$A$579,$A11,'Por foco'!$B$2:$B$579,$B11) -> 0 | K11: =SUMIFS('Por foco'!$L$2:$L$579,'Por foco'!$A$2:$A$579,$A11,'Por foco'!$B$2:$B$579,$B11) -> 0 | L11: =SUMIFS('Por foco'!$M$2:$M$579,'Por foco'!$A$2:$A$579,$A11,'Por foco'!$B$2:$B$579,$B11) -> 0 | M11: =SUMIFS('Por foco'!$N$2:$N$579,'Por foco'!$A$2:$A$579,$A11,'Por foco'!$B$2:$B$579,$B11) -> 2 | N11: =SUMIFS('Por foco'!$O$2:$O$579,'Por foco'!$A$2:$A$579,$A11,'Por foco'!$B$2:$B$579,$B11) -> 2 | O11: =SUMIFS('Por foco'!$P$2:$P$579,'Por foco'!$A$2:$A$579,$A11,'Por foco'!$B$2:$B$579,$B11) -> 0 | P11: =SUMIFS('Por foco'!$Q$2:$Q$579,'Por foco'!$A$2:$A$579,$A11,'Por foco'!$B$2:$B$579,$B11) -> 0 | Q11: =SUMIFS('Por foco'!$R$2:$R$579,'Por foco'!$A$2:$A$579,$A11,'Por foco'!$B$2:$B$579,$B11) -> 0 | R11: =SUMIFS('Por foco'!$S$2:$S$579,'Por foco'!$A$2:$A$579,$A11,'Por foco'!$B$2:$B$579,$B11) -> 0 | S11: =SUMIFS('Por foco'!$T$2:$T$579,'Por foco'!$A$2:$A$579,$A11,'Por foco'!$B$2:$B$579,$B11) -> 0 | T11: =SUMIFS('Por foco'!$U$2:$U$579,'Por foco'!$A$2:$A$579,$A11,'Por foco'!$B$2:$B$579,$B11) -> 0 | U11: =SUMIFS('Por foco'!$V$2:$V$579,'Por foco'!$A$2:$A$579,$A11,'Por foco'!$B$2:$B$579,$B11) -> 0 | V11: =SUMIFS('Por foco'!$W$2:$W$579,'Por foco'!$A$2:$A$579,$A11,'Por foco'!$B$2:$B$579,$B11) -> 0 | W11: =SUMIFS('Por foco'!$X$2:$X$579,'Por foco'!$A$2:$A$579,$A11,'Por foco'!$B$2:$B$579,$B11) -> 3
A12: ASC | B12: consejo_sorteado | C12: =COUNTIFS('Por foco'!$A$2:$A$579,$A12,'Por foco'!$B$2:$B$579,$B12) -> 9 | D12: =SUMIFS('Por foco'!$E$2:$E$579,'Por foco'!$A$2:$A$579,$A12,'Por foco'!$B$2:$B$579,$B12) -> 560 | E12: =SUMIFS('Por foco'!$F$2:$F$579,'Por foco'!$A$2:$A$579,$A12,'Por foco'!$B$2:$B$579,$B12) -> 300 | F12: =SUMIFS('Por foco'!$G$2:$G$579,'Por foco'!$A$2:$A$579,$A12,'Por foco'!$B$2:$B$579,$B12) -> 0 | G12: =SUMIFS('Por foco'!$H$2:$H$579,'Por foco'!$A$2:$A$579,$A12,'Por foco'!$B$2:$B$579,$B12) -> 5 | H12: =SUMIFS('Por foco'!$I$2:$I$579,'Por foco'!$A$2:$A$579,$A12,'Por foco'!$B$2:$B$579,$B12) -> 0 | I12: =SUMIFS('Por foco'!$J$2:$J$579,'Por foco'!$A$2:$A$579,$A12,'Por foco'!$B$2:$B$579,$B12) -> 50 | J12: =SUMIFS('Por foco'!$K$2:$K$579,'Por foco'!$A$2:$A$579,$A12,'Por foco'!$B$2:$B$579,$B12) -> 0 | K12: =SUMIFS('Por foco'!$L$2:$L$579,'Por foco'!$A$2:$A$579,$A12,'Por foco'!$B$2:$B$579,$B12) -> 0 | L12: =SUMIFS('Por foco'!$M$2:$M$579,'Por foco'!$A$2:$A$579,$A12,'Por foco'!$B$2:$B$579,$B12) -> 1 | M12: =SUMIFS('Por foco'!$N$2:$N$579,'Por foco'!$A$2:$A$579,$A12,'Por foco'!$B$2:$B$579,$B12) -> 0 | N12: =SUMIFS('Por foco'!$O$2:$O$579,'Por foco'!$A$2:$A$579,$A12,'Por foco'!$B$2:$B$579,$B12) -> 0 | O12: =SUMIFS('Por foco'!$P$2:$P$579,'Por foco'!$A$2:$A$579,$A12,'Por foco'!$B$2:$B$579,$B12) -> 0 | P12: =SUMIFS('Por foco'!$Q$2:$Q$579,'Por foco'!$A$2:$A$579,$A12,'Por foco'!$B$2:$B$579,$B12) -> 0 | Q12: =SUMIFS('Por foco'!$R$2:$R$579,'Por foco'!$A$2:$A$579,$A12,'Por foco'!$B$2:$B$579,$B12) -> 0 | R12: =SUMIFS('Por foco'!$S$2:$S$579,'Por foco'!$A$2:$A$579,$A12,'Por foco'!$B$2:$B$579,$B12) -> 0 | S12: =SUMIFS('Por foco'!$T$2:$T$579,'Por foco'!$A$2:$A$579,$A12,'Por foco'!$B$2:$B$579,$B12) -> 0 | T12: =SUMIFS('Por foco'!$U$2:$U$579,'Por foco'!$A$2:$A$579,$A12,'Por foco'!$B$2:$B$579,$B12) -> 0 | U12: =SUMIFS('Por foco'!$V$2:$V$579,'Por foco'!$A$2:$A$579,$A12,'Por foco'!$B$2:$B$579,$B12) -> 0 | V12: =SUMIFS('Por foco'!$W$2:$W$579,'Por foco'!$A$2:$A$579,$A12,'Por foco'!$B$2:$B$579,$B12) -> 1 | W12: =SUMIFS('Por foco'!$X$2:$X$579,'Por foco'!$A$2:$A$579,$A12,'Por foco'!$B$2:$B$579,$B12) -> 5
A13: ASC | B13: plan_41 | C13: =COUNTIFS('Por foco'!$A$2:$A$579,$A13,'Por foco'!$B$2:$B$579,$B13) -> 9 | D13: =SUMIFS('Por foco'!$E$2:$E$579,'Por foco'!$A$2:$A$579,$A13,'Por foco'!$B$2:$B$579,$B13) -> 595 | E13: =SUMIFS('Por foco'!$F$2:$F$579,'Por foco'!$A$2:$A$579,$A13,'Por foco'!$B$2:$B$579,$B13) -> 100 | F13: =SUMIFS('Por foco'!$G$2:$G$579,'Por foco'!$A$2:$A$579,$A13,'Por foco'!$B$2:$B$579,$B13) -> 0 | G13: =SUMIFS('Por foco'!$H$2:$H$579,'Por foco'!$A$2:$A$579,$A13,'Por foco'!$B$2:$B$579,$B13) -> 5 | H13: =SUMIFS('Por foco'!$I$2:$I$579,'Por foco'!$A$2:$A$579,$A13,'Por foco'!$B$2:$B$579,$B13) -> 100000 | I13: =SUMIFS('Por foco'!$J$2:$J$579,'Por foco'!$A$2:$A$579,$A13,'Por foco'!$B$2:$B$579,$B13) -> 0 | J13: =SUMIFS('Por foco'!$K$2:$K$579,'Por foco'!$A$2:$A$579,$A13,'Por foco'!$B$2:$B$579,$B13) -> 0 | K13: =SUMIFS('Por foco'!$L$2:$L$579,'Por foco'!$A$2:$A$579,$A13,'Por foco'!$B$2:$B$579,$B13) -> 0 | L13: =SUMIFS('Por foco'!$M$2:$M$579,'Por foco'!$A$2:$A$579,$A13,'Por foco'!$B$2:$B$579,$B13) -> 1 | M13: =SUMIFS('Por foco'!$N$2:$N$579,'Por foco'!$A$2:$A$579,$A13,'Por foco'!$B$2:$B$579,$B13) -> 2 | N13: =SUMIFS('Por foco'!$O$2:$O$579,'Por foco'!$A$2:$A$579,$A13,'Por foco'!$B$2:$B$579,$B13) -> 0 | O13: =SUMIFS('Por foco'!$P$2:$P$579,'Por foco'!$A$2:$A$579,$A13,'Por foco'!$B$2:$B$579,$B13) -> 0 | P13: =SUMIFS('Por foco'!$Q$2:$Q$579,'Por foco'!$A$2:$A$579,$A13,'Por foco'!$B$2:$B$579,$B13) -> 0 | Q13: =SUMIFS('Por foco'!$R$2:$R$579,'Por foco'!$A$2:$A$579,$A13,'Por foco'!$B$2:$B$579,$B13) -> 0 | R13: =SUMIFS('Por foco'!$S$2:$S$579,'Por foco'!$A$2:$A$579,$A13,'Por foco'!$B$2:$B$579,$B13) -> 0 | S13: =SUMIFS('Por foco'!$T$2:$T$579,'Por foco'!$A$2:$A$579,$A13,'Por foco'!$B$2:$B$579,$B13) -> 0 | T13: =SUMIFS('Por foco'!$U$2:$U$579,'Por foco'!$A$2:$A$579,$A13,'Por foco'!$B$2:$B$579,$B13) -> 0 | U13: =SUMIFS('Por foco'!$V$2:$V$579,'Por foco'!$A$2:$A$579,$A13,'Por foco'!$B$2:$B$579,$B13) -> 0 | V13: =SUMIFS('Por foco'!$W$2:$W$579,'Por foco'!$A$2:$A$579,$A13,'Por foco'!$B$2:$B$579,$B13) -> 0 | W13: =SUMIFS('Por foco'!$X$2:$X$579,'Por foco'!$A$2:$A$579,$A13,'Por foco'!$B$2:$B$579,$B13) -> 3
... A87: JUNTA | B87: mando_supremo | C87: =COUNTIFS('Por foco'!$A$2:$A$579,$A87,'Por foco'!$B$2:$B$579,$B87) -> 1 | D87: =SUMIFS('Por foco'!$E$2:$E$579,'Por foco'!$A$2:$A$579,$A87,'Por foco'!$B$2:$B$579,$B87) -> 70 | E87: =SUMIFS('Por foco'!$F$2:$F$579,'Por foco'!$A$2:$A$579,$A87,'Por foco'!$B$2:$B$579,$B87) -> 0 | F87: =SUMIFS('Por foco'!$G$2:$G$579,'Por foco'!$A$2:$A$579,$A87,'Por foco'!$B$2:$B$579,$B87) -> 0 | G87: =SUMIFS('Por foco'!$H$2:$H$579,'Por foco'!$A$2:$A$579,$A87,'Por foco'!$B$2:$B$579,$B87) -> 0 | H87: =SUMIFS('Por foco'!$I$2:$I$579,'Por foco'!$A$2:$A$579,$A87,'Por foco'!$B$2:$B$579,$B87) -> 500000 | I87: =SUMIFS('Por foco'!$J$2:$J$579,'Por foco'!$A$2:$A$579,$A87,'Por foco'!$B$2:$B$579,$B87) -> 0 | J87: =SUMIFS('Por foco'!$K$2:$K$579,'Por foco'!$A$2:$A$579,$A87,'Por foco'!$B$2:$B$579,$B87) -> 0 | K87: =SUMIFS('Por foco'!$L$2:$L$579,'Por foco'!$A$2:$A$579,$A87,'Por foco'!$B$2:$B$579,$B87) -> 0 | L87: =SUMIFS('Por foco'!$M$2:$M$579,'Por foco'!$A$2:$A$579,$A87,'Por foco'!$B$2:$B$579,$B87) -> 0 | M87: =SUMIFS('Por foco'!$N$2:$N$579,'Por foco'!$A$2:$A$579,$A87,'Por foco'!$B$2:$B$579,$B87) -> 0 | N87: =SUMIFS('Por foco'!$O$2:$O$579,'Por foco'!$A$2:$A$579,$A87,'Por foco'!$B$2:$B$579,$B87) -> 0 | O87: =SUMIFS('Por foco'!$P$2:$P$579,'Por foco'!$A$2:$A$579,$A87,'Por foco'!$B$2:$B$579,$B87) -> 0 | P87: =SUMIFS('Por foco'!$Q$2:$Q$579,'Por foco'!$A$2:$A$579,$A87,'Por foco'!$B$2:$B$579,$B87) -> 0 | Q87: =SUMIFS('Por foco'!$R$2:$R$579,'Por foco'!$A$2:$A$579,$A87,'Por foco'!$B$2:$B$579,$B87) -> 0 | R87: =SUMIFS('Por foco'!$S$2:$S$579,'Por foco'!$A$2:$A$579,$A87,'Por foco'!$B$2:$B$579,$B87) -> 0 | S87: =SUMIFS('Por foco'!$T$2:$T$579,'Por foco'!$A$2:$A$579,$A87,'Por foco'!$B$2:$B$579,$B87) -> 80000 | T87: =SUMIFS('Por foco'!$U$2:$U$579,'Por foco'!$A$2:$A$579,$A87,'Por foco'!$B$2:$B$579,$B87) -> 0 | U87: =SUMIFS('Por foco'!$V$2:$V$579,'Por foco'!$A$2:$A$579,$A87,'Por foco'!$B$2:$B$579,$B87) -> 0 | V87: =SUMIFS('Por foco'!$W$2:$W$579,'Por foco'!$A$2:$A$579,$A87,'Por foco'!$B$2:$B$579,$B87) -> 0 | W87: =SUMIFS('Por foco'!$X$2:$X$579,'Por foco'!$A$2:$A$579,$A87,'Por foco'!$B$2:$B$579,$B87) -> 1

Sheet Por foco
A1: Árbol | B1: Rama | C1: Foco | D1: Nombre | E1: Días | F1: Poder político | G1: Estabilidad (%) | H1: Apoyo a la guerra (%) | I1: Mano de obra | J1: Exp. ejército | K1: Exp. naval | L1: Exp. aérea | M1: Casillas de investigación | N1: Bonos de tecnología (usos) | O1: Fábricas civiles | P1: Fábricas militares | Q1: Astilleros | R1: Infraestructura | S1: Otros edificios (niveles) | T1: Equipo (unidades) | U1: Divisiones | V1: Cazas gratis | W1: Reclamos, núcleos y objetivos | X1: Espíritus (agregados) | Y1: Espíritus (detalle) | Z1: Mecánica | AA1: Excluye a
A2: EFE | B2: dinastia_verde | C2: EFE_custodio_de_la_tierra | D2: Custodio de la Tierra | E2: 49 | F2: 100 | G2: 0 | H2: 0 | I2: 0 | J2: 0 | K2: 0 | L2: 0 | M2: 0 | N2: 0 | O2: 0 | P2: 0 | Q2: 0 | R2: 0 | S2: 0 | T2: 0 | U2: 0 | V2: 0 | W2: 0 | X2: 0
A3: EFE | B3: dinastia_verde | C3: EFE_la_hora_de_gaia | D3: La Hora de Gaia | E3: 49 | F3: 100 | G3: 0 | H3: 0 | I3: 0 | J3: 0 | K3: 0 | L3: 0 | M3: 0 | N3: 0 | O3: 0 | P3: 0 | Q3: 0 | R3: 0 | S3: 0 | T3: 0 | U3: 0 | V3: 0 | W3: 0 | X3: 0
A4: EFE | B4: dinastia_verde | C4: EFE_el_mandato_renovado | D4: El Mandato Renovado | E4: 49 | F4: 100 | G4: 0 | H4: 0 | I4: 0 | J4: 0 | K4: 0 | L4: 0 | M4: 0 | N4: 0 | O4: 0 | P4: 0 | Q4: 0 | R4: 0 | S4: 0 | T4: 0 | U4: 0 | V4: 0 | W4: 0 | X4: 0 | AA4: EFE_los_incendios_de_gaia
A5: EFE | B5: dinastia_verde | C5: EFE_la_corte_de_los_bosques | D5: La Corte de los Bosques | E5: 49 | F5: 0 | G5: 0 | H5: 0 | I5: 0 | J5: 0 | K5: 0 | L5: 0 | M5: 0 | N5: 0 | O5: 0 | P5: 0 | Q5: 0 | R5: 0 | S5: 0 | T5: 0 | U5: 0 | V5: 0 | W5: 0 | X5: 1 | Y5: EFE_trono_del_bosque, - EFE_corte_dividida
A6: EFE | B6: dinastia_verde | C6: EFE_heredero_de_la_tierra | D6: Heredero de la Tierra | E6: 84 | F6: 100 | G6: 0 | H6: 0 | I6: 0 | J6: 0 | K6: 0 | L6: 0 | M6: 0 | N6: 0 | O6: 0 | P6: 0 | Q6: 0 | R6: 0 | S6: 0 | T6: 0 | U6: 0 | V6: 0 | W6: 0 | X6: 0 | Z6: EFE_biosteel +2, EFE_saturacion +6
A7: EFE | B7: dinastia_verde | C7: EFE_las_misiones_guaranies | D7: Las Misiones Guaraníes | E7: 63 | F7: 100 | G7: 0 | H7: 0 | I7: 0 | J7: 0 | K7: 0 | L7: 0 | M7: 0 | N7: 0 | O7: 0 | P7: 0 | Q7: 0 | R7: 0 | S7: 0 | T7: 0 | U7: 0 | V7: 0 | W7: 1 | X7: 0
A8: EFE | B8: dinastia_verde | C8: EFE_integrar_la_patagonia | D8: Integrar la Patagonia Austral | E8: 63 | F8: 100 | G8: 0 | H8: 0 | I8: 0 | J8: 0 | K8: 0 | L8: 0 | M8: 0 | N8: 0 | O8: 0 | P8: 0 | Q8: 0 | R8: 0 | S8: 0 | T8: 0 | U8: 0 | V8: 0 | W8: 1 | X8: 0
A9: EFE | B9: dinastia_verde | C9: EFE_la_gran_muralla_verde | D9: La Gran Muralla Verde | E9: 63 | F9: 0 | G9: 0 | H9: 0 | I9: 0 | J9: 0 | K9: 0 | L9: 0 | M9: 0 | N9: 0 | O9: 0 | P9: 0 | Q9: 0 | R9: 0 | S9: 0 | T9: 0 | U9: 0 | V9: 0 | W9: 0 | X9: 1 | Y9: EFE_muralla_verde
A10: EFE | B10: dinastia_verde | C10: EFE_guardian_del_acuifero | D10: Guardián del Acuífero | E10: 49 | F10: 0 | G10: 0 | H10: 0 | I10: 0 | J10: 0 | K10: 0 | L10: 0 | M10: 0 | N10: 0 | O10: 0 | P10: 0 | Q10: 0 | R10: 0 | S10: 0 | T10: 0 | U10: 0 | V10: 0 | W10: 0 | X10: 1 | Y10: EFE_defensa_acuifero
A11: EFE | B11: dinastia_verde | C11: EFE_el_agua_no_se_vende | D11: El Agua no se Vende | E11: 105 | F11: 0 | G11: 0 | H11: 5 | I11: 0 | J11: 0 | K11: 0 | L11: 0 | M11: 0 | N11: 0 | O11: 0 | P11: 0 | Q11: 0 | R11: 0 | S11: 0 | T11: 0 | U11: 0 | V11: 0 | W11: 0 | X11: 0
